Workbook

Sheet Допускания
A1: Водна Оценка · Агенционен Канал — Допускания
A2: Редактирайте светлозелените клетки — формулите в „Резюме" се актуализират автоматично
A4: Параметър | B4: Година 1 | C4: Година 2 | D4: Година 3 | E4: Бележка
A5: ОБЕМ (брой обекти на година)
A6: Обявни оценки | B6: 300 | C6: 1100 | D6: 2600 | E6: Обявна оценка — агенционен абонамент
A7: Купувачски проверки | B7: 40 | C7: 160 | D7: 400 | E7: Купувачска проверка с гаранция
A8: Кабинетни справки | B8: 0 | C8: 150 | D8: 600 | E8: Само от покрити райони (Г2+)
A9: ЦЕНИ НЕТО (€ без ДДС — постъпление към вас)
A10: Обявна оценка (ср. при абонамент) | B10: 152 | E10: Пакет S €190 → L €150, ср. ~€160
A11: Купувачска проверка | B11: 272 | E11: €390 с ДДС → €325 нето
A12: Кабинетна справка | B12: 52 | E12: €59 с ДДС → €49 нето
A13: ПРЕКИ РАЗХОДИ (€ на обект)
A14: Обявна оценка | B14: 18 | E14: Гориво ~€8 + консумативи ~€10
A15: Купувачска проверка | B15: 44 | E15: Три профила, по-дълго на терен
A16: Кабинетна справка | B16: 3 | E16: Само 20 мин бюро-работа
A17: ПЕРСОНАЛ
A18: Брой оператори (бр.) | B18: 1 | C18: 2 | D18: 4 | E18: Пълен работен ден с кола и уред
A19: Разход/оператор/месец (бруто работодател) | B19: 2600 | E19: Заплата + осигуровки ~38%
A20: ПОСТОЯННИ РАЗХОДИ (€ / месец)
A21: Маркетинг | B21: 700 | C21: 1500 | D21: 2600 | E21: Google Ads, SEO, визитки, изложения
A22: Автомобил (гориво + поддръжка) | B22: 250 | E22: Колата е купена от началния капитал
A23: Застраховки (проф. отговорност + ГО) | B23: 180
A24: Счетоводство + офис | B24: 300
A25: СТАРТОВИ РАЗХОДИ (еднократно, Месец 1)
A26: Геофизичен уред (NEF апаратура) | B26: 5000 | E26: Или лизинг ~€150/м → по-нисък стартов кеш
A27: Лек автомобил (покупка) | B27: 8000 | E27: Алт.: лизинг €350/м
A28: Юридически договори + сайт + бранд | B28: 2500
A29: НАЧАЛЕН КАПИТАЛ
A30: Начална каса (собствен капитал / заем) | B30: 22000
A31: Нетен буфер след стартови разходи | B31: 6500
A33: ⚠ Листът „Резюме" използва формули, свързани с тези клетки. При промяна на стойностите тук, „Резюме" се актуализира автоматично. Листовете „Приходи", „Разходи" и „Парични потоци" отразяват базовите стойности (изчислени при генериране).

Sheet Резюме
A1: Водна Оценка · Агенционен Канал — Резюме
A3: Всички стойности без ДДС, в евро. Формулите са свързани с листа „Допускания".
A4: Приходи и разходи | B4: Година 1 | C4: Година 2 | D4: Година 3 | E4: Бележка
A5: ПРИХОДИ
A6: Обявни оценки (агенционен канал) | B6: ='Допускания'!B6*'Допускания'!B10 | C6: ='Допускания'!C6*'Допускания'!B10 | D6: ='Допускания'!D6*'Допускания'!B10 | E6: Листингови оценки: обем × цена
A7: Купувачски проверки | B7: ='Допускания'!B7*'Допускания'!B11 | C7: ='Допускания'!C7*'Допускания'!B11 | D7: ='Допускания'!D7*'Допускания'!B11 | E7: Купувачски: по-дълбока проверка
A8: Кабинетни справки | B8: ='Допускания'!B8*'Допускания'!B12 | C8: ='Допускания'!C8*'Допускания'!B12 | D8: ='Допускания'!D8*'Допускания'!B12 | E8: Кабинетни: от натрупана база данни
A9: Общо приходи | B9: =SUM(B6:B8) | C9: =SUM(C6:C8) | D9: =SUM(D6:D8) | E9: Сумарен приход
A10: ПРЕКИ РАЗХОДИ
A11: Обявни оценки | B11: ='Допускания'!B6*'Допускания'!B14 | C11: ='Допускания'!C6*'Допускания'!B14 | D11: ='Допускания'!D6*'Допускания'!B14 | E11: Директни разходи за измерване
A12: Купувачски проверки | B12: ='Допускания'!B7*'Допускания'!B15 | C12: ='Допускания'!C7*'Допускания'!B15 | D12: ='Допускания'!D7*'Допускания'!B15 | E12: Включва 3 профила + документи
A13: Кабинетни справки | B13: ='Допускания'!B8*'Допускания'!B16 | C13: ='Допускания'!C8*'Допускания'!B16 | D13: ='Допускания'!D8*'Допускания'!B16 | E13: Само бюро-работа, без терен
A14: Общо преки разходи | B14: =SUM(B11:B13) | C14: =SUM(C11:C13) | D14: =SUM(D11:D13) | E14: Директни разходи общо
A15: БРУТНА ПЕЧАЛБА | B15: =B9-B14 | C15: =C9-C14 | D15: =D9-D14 | E15: Приход − директни разходи
A16: Брутен марж (%) | B16: =IF(B9=0,0,B15/B9) | C16: =IF(C9=0,0,C15/C9) | D16: =IF(D9=0,0,D15/D9)
A17: ОПЕРАТИВНИ РАЗХОДИ
A18: Оператори | B18: ='Допускания'!B18*'Допускания'!B19*12 | C18: ='Допускания'!C18*'Допускания'!B19*12 | D18: ='Допускания'!D18*'Допускания'!B19*12 | E18: Google Ads, препоръки, изложения
A19: Маркетинг | B19: ='Допускания'!B21*12 | C19: ='Допускания'!C21*12 | D19: ='Допускания'!D21*12 | E19: Автомобил + застраховки + счетоводство
A20: Постоянни (кола + застр. + счет.) | B20: =('Допускания'!B22+'Допускания'!B23+'Допускания'!B24)*12 | C20: =('Допускания'!B22+'Допускания'!B23+'Допускания'!B24)*12 | D20: =('Допускания'!B22+'Допускания'!B23+'Допускания'!B24)*12 | E20: Оперативни разходи общо
A21: Общо оперативни разходи | B21: =SUM(B18:B20) | C21: =SUM(C18:C20) | D21: =SUM(D18:D20) | E21: Брутна печалба − оперативни разходи
A22: EBITDA | B22: =B15-B21 | C22: =C15-C21 | D22: =D15-D21
A23: EBITDA марж (%) | B23: =IF(B9=0,0,B22/B9) | C23: =IF(C9=0,0,C22/C9) | D23: =IF(D9=0,0,D22/D9) | E23: Само Г1: уред + кола + юридически
A24: СТАРТОВИ РАЗХОДИ И НЕТЕН ПАРИЧЕН ПОТОК
A25: Стартови разходи (само Г1) | B25: ='Допускания'!B26+'Допускания'!B27+'Допускания'!B28 | C25: 0 | D25: 0
A26: НЕТЕН ПАРИЧЕН ПОТОК | B26: =B22-B25 | C26: =C22-C25 | D26: =D22-D25

Sheet Приходи
A1: Водна Оценка · Приходи по продукт
A3: ОБЕМ (брой обекти)
A4: Продукт | B4: Година 1 | C4: Година 2 | D4: Година 3 | E4: Ср. ръст | F4: Бележка
A5: Обявни оценки | B5: 300 | C5: 1100 | D5: 2600 | E5: 1.9439203 | F5: 300 → 1100 → 2600
A6: Купувачски проверки | B6: 40 | C6: 160 | D6: 400 | E6: 2.1622777 | F6: 40 → 160 → 400
A7: Кабинетни справки | B7: 0 | C7: 150 | D7: 600 | E7: 0 | F7: 0 → 150 → 600
A8: Общо обекти | B8: 340 | C8: 1410 | D8: 3600
A10: ПРИХОДИ (€ нето)
A11: Продукт | B11: Година 1 | C11: Година 2 | D11: Година 3 | E11: Дял Г3 | F11: Цена нето
A12: Обявни оценки | B12: 45600 | C12: 167200 | D12: 395200 | E12: 0.73841555 | F12: €152/оценка
A13: Купувачски проверки | B13: 10880 | C13: 43520 | D13: 108800 | E13: 0.20328849 | F13: €272/проверка
A14: Кабинетни справки | B14: 0 | C14: 7800 | D14: 31200 | E14: 0.058295964 | F14: €52/справка
A15: Общо приходи | B15: 56480 | C15: 218520 | D15: 535200
A17: ЕДИНИЧНА ИКОНОМИКА
A18: Продукт | B18: Цена нето | C18: Пряк разход | D18: Принос/обект | E18: Марж | F18: Капацитет г/оп.
A19: Обявна оценка | B19: 152 | C19: 18 | D19: 134 | E19: 0.88157895 | F19: ~800 бр.
A20: Купувачска проверка | B20: 272 | C20: 44 | D20: 228 | E20: 0.83823529 | F20: ~200 бр.
A21: Кабинетна справка | B21: 52 | C21: 3 | D21: 49 | E21: 0.94230769 | F21: Неограничено

Sheet Разходи
A1: Водна Оценка · Разходна структура
A3: СТРУКТУРА НА РАЗХОДИТЕ (€)
A4: Категория | B4: Г1 (€) | C4: Г1 (%) | D4: Г2 (€) | E4: Г2 (%) | F4: Г3 (€) | G4: Г3 (%)
A5: Преки разходи (сумарно) | B5: 7160 | C5: 0.10081667 | D5: 27290 | E5: 0.23434951 | F5: 66200 | G5: 0.28662972
A6: Обявни оценки | B6: 5400 | C6: 0.07603492 | D6: 19800 | E6: 0.17003006 | F6: 46800 | G6: 0.20263249
A7: Купувачски проверки | B7: 1760 | C7: 0.024781752 | D7: 7040 | E7: 0.060455131 | F7: 17600 | G7: 0.076203672
A8: Кабинетни справки | B8: 0 | C8: 0 | D8: 450 | E8: 0.0038643195 | F8: 1800 | G8: 0.0077935573
A9: Оператори | B9: 31200 | C9: 0.43931287 | D9: 62400 | E9: 0.5358523 | F9: 124800 | G9: 0.54035331
A10: Маркетинг | B10: 8400 | C10: 0.11827654 | D10: 18000 | E10: 0.15457278 | F10: 31200 | G10: 0.13508833
A11: Постоянни (кола+застр.+счет.) | B11: 8760 | C11: 0.12334554 | D11: 8760 | E11: 0.075225419 | F11: 8760 | G11: 0.037928646
A12: Стартови разходи | B12: 15500 | C12: 0.21824838 | D12: 0 | E12: 0 | F12: 0 | G12: 0
A13: Общо разходи | B13: 71020 | C13: 1 | D13: 116450 | E13: 1 | F13: 230960 | G13: 1
A15: МАРЖОВА ЕВОЛЮЦИЯ
A16: Показател | B16: Г1 | C16: (€) | D16: Г2 | E16: (€) | F16: Г3 | G16: (€)
A17: Приходи | B17: 56480 | D17: 218520 | F17: 535200
A18: Брутна печалба | B18: 49320 | C18: 0.87322946 | D18: 191230 | E18: 0.87511441 | F18: 469000 | G18: 0.87630792
A19: EBITDA | B19: 960 | C19: 0.016997167 | D19: 102070 | E19: 0.46709683 | F19: 304240 | G19: 0.56846039
A20: Нетен паричен поток | B20: -14540 | D20: 102070 | F20: 304240

Sheet Парични потоци
A1: Водна Оценка · Месечни парични потоци (36 месеца)
A3: Минимален касов баланс: €2,671 (М3, Мар Г1) · Първи положителен EBITDA: М4 (Апр Г1) · Начална каса: €22,000
A4: Мес. | B4: Г | C4: Месец | D4: Приход | E4: Пр. разходи | F4: Бр. печалба | G4: Опер. разх. | H4: EBITDA | I4: Стартови | J4: Нетен ПП | K4: Касов баланс
A5: 1 | B5: 1 | C5: Яну | D5: 2588.6667 | E5: 328.16667 | F5: 2260.5 | G5: 4030 | H5: -1769.5 | I5: 15500 | J5: -17269.5 | K5: 4730.5
A6: 2 | B6: 1 | C6: Фев | D6: 2729.8667 | E6: 346.06667 | F6: 2383.8 | G6: 4030 | H6: -1646.2 | I6: 0 | J6: -1646.2 | K6: 3084.3
A7: 3 | B7: 1 | C7: Мар | D7: 4141.8667 | E7: 525.06667 | F7: 3616.8 | G7: 4030 | H7: -413.2 | I7: 0 | J7: -413.2 | K7: 2671.1
A8: 4 | B8: 1 | C8: Апр | D8: 5648 | E8: 716 | F8: 4932 | G8: 4030 | H8: 902 | I8: 0 | J8: 902 | K8: 3573.1
A9: 5 | B9: 1 | C9: Май | D9: 6495.2 | E9: 823.4 | F9: 5671.8 | G9: 4030 | H9: 1641.8 | I9: 0 | J9: 1641.8 | K9: 5214.9
A10: 6 | B10: 1 | C10: Юни | D10: 5742.1333 | E10: 727.93333 | F10: 5014.2 | G10: 4030 | H10: 984.2 | I10: 0 | J10: 984.2 | K10: 6199.1
A11: 7 | B11: 1 | C11: Юли | D11: 4942 | E11: 626.5 | F11: 4315.5 | G11: 4030 | H11: 285.5 | I11: 0 | J11: 285.5 | K11: 6484.6
A12: 8 | B12: 1 | C12: Авг | D12: 4800.8 | E12: 608.6 | F12: 4192.2 | G12: 4030 | H12: 162.2 | I12: 0 | J12: 162.2 | K12: 6646.8
A13: 9 | B13: 1 | C13: Сеп | D13: 5883.3333 | E13: 745.83333 | F13: 5137.5 | G13: 4030 | H13: 1107.5 | I13: 0 | J13: 1107.5 | K13: 7754.3
A14: 10 | B14: 1 | C14: Окт | D14: 6495.2 | E14: 823.4 | F14: 5671.8 | G14: 4030 | H14: 1641.8 | I14: 0 | J14: 1641.8 | K14: 9396.1
A15: 11 | B15: 1 | C15: Ное | D15: 4236 | E15: 537 | F15: 3699 | G15: 4030 | H15: -331 | I15: 0 | J15: -331 | K15: 9065.1
A16: 12 | B16: 1 | C16: Дек | D16: 2776.9333 | E16: 352.03333 | F16: 2424.9 | G16: 4030 | H16: -1605.1 | I16: 0 | J16: -1605.1 | K16: 7460
C17: Г1 — Общо | D17: 56480 | E17: 7160 | F17: 49320 | G17: 48360 | H17: 960 | I17: 15500 | J17: -14540 | K17: 7460
A18: 13 | B18: 2 | C18: Яну | D18: 10015.5 | E18: 1250.7917 | F18: 8764.7083 | G18: 7430 | H18: 1334.7083 | I18: 0 | J18: 1334.7083 | K18: 8794.7083
A19: 14 | B19: 2 | C19: Фев | D19: 10561.8 | E19: 1319.0167 | F19: 9242.7833 | G19: 7430 | H19: 1812.7833 | I19: 0 | J19: 1812.7833 | K19: 10607.492
A20: 15 | B20: 2 | C20: Мар | D20: 16024.8 | E20: 2001.2667 | F20: 14023.533 | G20: 7430 | H20: 6593.5333 | I20: 0 | J20: 6593.5333 | K20: 17201.025
A21: 16 | B21: 2 | C21: Апр | D21: 21852 | E21: 2729 | F21: 19123 | G21: 7430 | H21: 11693 | I21: 0 | J21: 11693 | K21: 28894.025
A22: 17 | B22: 2 | C22: Май | D22: 25129.8 | E22: 3138.35 | F22: 21991.45 | G22: 7430 | H22: 14561.45 | I22: 0 | J22: 14561.45 | K22: 43455.475
A23: 18 | B23: 2 | C23: Юни | D23: 22216.2 | E23: 2774.4833 | F23: 19441.717 | G23: 7430 | H23: 12011.717 | I23: 0 | J23: 12011.717 | K23: 55467.192
A24: 19 | B24: 2 | C24: Юли | D24: 19120.5 | E24: 2387.875 | F24: 16732.625 | G24: 7430 | H24: 9302.625 | I24: 0 | J24: 9302.625 | K24: 64769.817
A25: 20 | B25: 2 | C25: Авг | D25: 18574.2 | E25: 2319.65 | F25: 16254.55 | G25: 7430 | H25: 8824.55 | I25: 0 | J25: 8824.55 | K25: 73594.367
A26: 21 | B26: 2 | C26: Сеп | D26: 22762.5 | E26: 2842.7083 | F26: 19919.792 | G26: 7430 | H26: 12489.792 | I26: 0 | J26: 12489.792 | K26: 86084.158
A27: 22 | B27: 2 | C27: Окт | D27: 25129.8 | E27: 3138.35 | F27: 21991.45 | G27: 7430 | H27: 14561.45 | I27: 0 | J27: 14561.45 | K27: 100645.61
A28: 23 | B28: 2 | C28: Ное | D28: 16389 | E28: 2046.75 | F28: 14342.25 | G28: 7430 | H28: 6912.25 | I28: 0 | J28: 6912.25 | K28: 107557.86
A29: 24 | B29: 2 | C29: Дек | D29: 10743.9 | E29: 1341.7583 | F29: 9402.1417 | G29: 7430 | H29: 1972.1417 | I29: 0 | J29: 1972.1417 | K29: 109530
C30: Г2 — Общо | D30: 218520 | E30: 27290 | F30: 191230 | G30: 89160 | H30: 102070 | I30: 0 | J30: 102070 | K30: 109530
A31: 25 | B31: 3 | C31: Яну | D31: 24530 | E31: 3034.1667 | F31: 21495.833 | G31: 13730 | H31: 7765.8333 | I31: 0 | J31: 7765.8333 | K31: 117295.83
A32: 26 | B32: 3 | C32: Фев | D32: 25868 | E32: 3199.6667 | F32: 22668.333 | G32: 13730 | H32: 8938.3333 | I32: 0 | J32: 8938.3333 | K32: 126234.17
A33: 27 | B33: 3 | C33: Мар | D33: 39248 | E33: 4854.6667 | F33: 34393.333 | G33: 13730 | H33: 20663.333 | I33: 0 | J33: 20663.333 | K33: 146897.5
A34: 28 | B34: 3 | C34: Апр | D34: 53520 | E34: 6620 | F34: 46900 | G34: 13730 | H34: 33170 | I34: 0 | J34: 33170 | K34: 180067.5
A35: 29 | B35: 3 | C35: Май | D35: 61548 | E35: 7613 | F35: 53935 | G35: 13730 | H35: 40205 | I35: 0 | J35: 40205 | K35: 220272.5
A36: 30 | B36: 3 | C36: Юни | D36: 54412 | E36: 6730.3333 | F36: 47681.667 | G36: 13730 | H36: 33951.667 | I36: 0 | J36: 33951.667 | K36: 254224.17
A37: 31 | B37: 3 | C37: Юли | D37: 46830 | E37: 5792.5 | F37: 41037.5 | G37: 13730 | H37: 27307.5 | I37: 0 | J37: 27307.5 | K37: 281531.67
A38: 32 | B38: 3 | C38: Авг | D38: 45492 | E38: 5627 | F38: 39865 | G38: 13730 | H38: 26135 | I38: 0 | J38: 26135 | K38: 307666.67
A39: 33 | B39: 3 | C39: Сеп | D39: 55750 | E39: 6895.8333 | F39: 48854.167 | G39: 13730 | H39: 35124.167 | I39: 0 | J39: 35124.167 | K39: 342790.83
A40: 34 | B40: 3 | C40: Окт | D40: 61548 | E40: 7613 | F40: 53935 | G40: 13730 | H40: 40205 | I40: 0 | J40: 40205 | K40: 382995.83
A41: 35 | B41: 3 | C41: Ное | D41: 40140 | E41: 4965 | F41: 35175 | G41: 13730 | H41: 21445 | I41: 0 | J41: 21445 | K41: 404440.83
...
