Workbook

Sheet Указания
B1: Финансов модел — интегратор на водни сондажи с гарантиран резултат
B2: Изготвен 7 септември 2026 г. Всички суми са в EUR, без ДДС, освен където изрично е посочено друго.
B5: КАК СЕ ПОЛЗВА
B6: Единственият лист за редактиране | C6: «Допускания». Всяко число там е вход на модела. Останалите листове са изцяло формули.
B7: Смяна на сценарий | C7: Допускания!C6 — въведи 1 (Консервативен), 2 (Базов) или 3 (Агресивен). Целият модел се преизчислява.
B8: След всяка промяна | C8: Ако отваряш в LibreOffice: Ctrl+Shift+F9 за пълно преизчисление.
B10: ЦВЕТОВИ КОД
B11: Син текст | C11: Твърдо въведено допускание — това са цифрите, които се сменят.
B12: Черен текст | C12: Формула в рамките на същия лист.
B13: Зелен текст | C13: Формула, която взима стойност от друг лист.
B14: Жълт фон | C14: Ключово допускание с висока чувствителност — провери го преди да вярваш на резултата.
B15: Оранжев фон | C15: Предупреждение или контролна проверка.
B17: ЛИСТОВЕ
B18: Допускания | C18: Всички входни параметри: сценарии, пакети, разходи, обеми, персонал, риск, капитал.
B19: Пакети | C19: Икономика на единица за всеки от трите пакета и за трите години. Показва къде се прави маржът.
B20: Обеми | C20: Месечни обеми за 36 месеца със сезонност и линеен метраж.
B21: ОПР | C21: Отчет за приходите и разходите, месечно за 36 месеца, с годишни суми.
B22: Паричен поток | C22: Месечен паричен поток, салдо и минимална точка. Тук се вижда колко капитал реално трябва.
B23: Гаранционен фонд | C23: Математиката на риска: очаквани неуспехи, разход по тях, покритие на фонда.
B24: Годишно резюме | C24: Трите години на един екран плюс основните показатели.
B25: Сценарии | C25: Трите сценария и таблица за чувствителност на EBITDA през година 3.
B27: ВАЖНИ ОГРАНИЧЕНИЯ
B28: Броят обекти е дробен | C28: Месечните обеми са дробни числа. Това е нормално за модел — не се закръглява, за да не се трупа грешка.
B29: Процентът неуспешни сондажи | C29: Няма публикувана статистика за България. Стойността в модела е допускане, не измерване. Това е най-чувствителният вход в целия файл — виж листа «Сценарии».
B30: ДДС | C30: Всички приходи са без ДДС. Физическото лице плаща цена + 20%. Виж реда «Цена с ДДС» в листа «Пакети» — това е числото, което клиентът сравнява с офертата на нерегистрирана бригада.
B31: Цените на подизпълнителя | C31: Изведени от публикувани пазарни цени (30–110 €/м за готов сондаж) минус договорена отстъпка при обем. Отстъпката е допускане до първия подписан рамков договор.

Sheet Допускания
B1: Допускания
B2: Синьото се редактира. Жълтият фон маркира входовете с най-голямо влияние върху резултата.
B4: 1. СЦЕНАРИЙ
B5: Избран сценарий (1 / 2 / 3) | C5: 2 | F5: 1=Консервативен, 2=Базов, 3=Агресивен
B6: Множител на обема | C6: =INDEX(Сценарии!$D$5:$F$5,1,$C$5) -> 1
B7: Множител на цените | C7: =INDEX(Сценарии!$D$6:$F$6,1,$C$5) -> 1
B8: Множител на цената на подизпълнителя | C8: =INDEX(Сценарии!$D$7:$F$7,1,$C$5) -> 1
B10: 2. ПАКЕТИ, ЦЕНИ И МИКС
B11: Пакет | C11: Дълбочина до (м) | D11: Списъчна цена г.1 (€) | E11: Средна реална дълбочина (м) | F11: Дял от обема
B12: A — до 30 м | C12: 30 | D12: 4900 | E12: 24 | F12: 0 | G12: =D12/E12 -> 204.16667
B13: B — до 60 м | C13: 60 | D13: 7300 | E13: 45 | F13: 0.65 | G13: =D13/E13 -> 162.22222
B14: C — до 100 м | C14: 100 | D14: 11500 | E14: 78 | F14: 0.35 | G14: =D14/E14 -> 147.4359
B15: Контрола: сборът на дяловете | F15: =SUM(F12:F14) -> 1 | G15: =IF(ROUND(F15,4)=1,"ОК","ГРЕШКА — трябва да е 100%") -> ОК
B16: Годишна индексация на продажните цени | C16: 0 | D16: 0.1 | E16: 0.1
B17: Ставка ДДС | C17: 0.2
B19: 3. РАЗХОДИ С ПОДИЗПЪЛНИТЕЛИ И МАТЕРИАЛИ
B20: Показател | C20: Година 1 | D20: Година 2 | E20: Година 3 | F20: Бележка
B21: Сондиране — договорена цена (€/линеен метър) | C21: 42 | D21: 38 | E21: 35 | F21: Пазарна цена само за сондиране 50 €/м. Отстъпката е за обем, бързо плащане и подготвен обект.
B22: Обсадни тръби — доставка от нас (€/метър) | C22: 16 | D22: 15 | E22: 15 | F22: PVC 125 мм, купени директно на едро без надценка на бригадата.
B23: Геофизично проучване на обект (външно, €) | C23: 50 | D23: 50 | E23: 50 | F23: Възлага се на външен геофизик. При покупка на собствена апаратура пада до ~120 €.
B24: Коефициент на ефективност по фиксираните разходи | C24: 1 | D24: 0.94 | E24: 0.9 | F24: Групови доставки, маршрутизация на обектите, по-малко празни курсове.
B26: Фиксирани преки разходи на обект, година 1 (без сондиране, обсадни и геофизика)
B27: Разходно перо | C27: Пакет A | D27: Пакет B | E27: Пакет C | F27: Бележка
B28: Филтърна секция | C28: 0 | D28: 0 | E28: 0
B29: Гравийна засипка | C29: 80 | D29: 100 | E29: 150
B30: Прочистване и водочерпене | C30: 100 | D30: 100 | E30: 100
B31: Тест на дебит | C31: 80 | D31: 90 | E31: 110 | F31: Доказва изпълнението на гаранцията — не се спестява.
B32: Капак и уплътнение на устието | C32: 60 | D32: 60 | E32: 70
B33: Водопроводна шахта — материали | C33: 340 | D33: 380 | E33: 430 | F33: Шахта, арматура, спирателен кран, връзки.
B34: Водопроводна шахта — монтаж | C34: 240 | D34: 260 | E34: 300 | F34: Изкоп, монтаж, затваряне.
B35: Геодезическо заснемане | C35: 90 | D35: 90 | E35: 90 | F35: Изисква се за регистрацията.
B36: Мобилизация на бригадата (дял) | C36: 150 | D36: 150 | E36: 200 | F36: Пада при маршрутизиране на 3–4 обекта в район.
B37: Логистика на материали | C37: 70 | D37: 80 | E37: 100
B38: Общо фиксирани преки разходи (г.1) | C38: =SUM(C28:C37) -> 1210 | D38: =SUM(D28:D37) -> 1310 | E38: =SUM(E28:E37) -> 1550
B40: 4. ДОПЪЛНИТЕЛНИ ПРОДАЖБИ
B41: Продукт | C41: Дял на обектите | D41: Цена (€) | E41: Разход (€) | F41: Бележка
B42: Помпа, хидрофор и автоматика | C42: 0.65 | D42: 1650 | E42: 1180 | F42: Не е в базовия пакет — продава се при предаването.
B43: Узаконяване и разрешително (стопански клиенти) | C43: 0.18 | D43: 5000 | E43: 2000 | F43: Само за клиенти над битовия лимит от 10 м³/ден.
B44: Химичен анализ на водата | C44: 0.75 | D44: 160 | E44: 95 | F44: Акредитирана лаборатория.
B45: Абонамент за мониторинг и съответствие — дял на обектите | C45: 0.1
...

Sheet Пакети
B1: Икономика на единица по пакет и по година
B2: Всичко е формула. Виж последните редове: маржът расте с дълбочината — фиксираните разходи не се свиват на плитките обекти.
B4: Година | C4: 1 | D4: 1 | E4: 1 | F4: 2 | G4: 2 | H4: 2 | I4: 3 | J4: 3 | K4: 3
B5: Пакет | C5: A | D5: B | E5: C | F5: A | G5: B | H5: C | I5: A | J5: B | K5: C
B6: Средна реална дълбочина (м) | C6: =Допускания!$E$12 -> 24 | D6: =Допускания!$E$13 -> 45 | E6: =Допускания!$E$14 -> 78 | F6: =Допускания!$E$12 -> 24 | G6: =Допускания!$E$13 -> 45 | H6: =Допускания!$E$14 -> 78 | I6: =Допускания!$E$12 -> 24 | J6: =Допускания!$E$13 -> 45 | K6: =Допускания!$E$14 -> 78
B7: Продажна цена, без ДДС (€) | C7: =Допускания!$D$12*(1+Допускания!$C$16)^0*Допускания!$C$7 -> 4900 | D7: =Допускания!$D$13*(1+Допускания!$C$16)^0*Допускания!$C$7 -> 7300 | E7: =Допускания!$D$14*(1+Допускания!$C$16)^0*Допускания!$C$7 -> 11500 | F7: =Допускания!$D$12*(1+Допускания!$D$16)^1*Допускания!$C$7 -> 5390 | G7: =Допускания!$D$13*(1+Допускания!$D$16)^1*Допускания!$C$7 -> 8030 | H7: =Допускания!$D$14*(1+Допускания!$D$16)^1*Допускания!$C$7 -> 12650 | I7: =Допускания!$D$12*(1+Допускания!$E$16)^2*Допускания!$C$7 -> 5929 | J7: =Допускания!$D$13*(1+Допускания!$E$16)^2*Допускания!$C$7 -> 8833 | K7: =Допускания!$D$14*(1+Допускания!$E$16)^2*Допускания!$C$7 -> 13915
B8: Цена с ДДС — това вижда физическото лице (€) | C8: =C7*(1+Допускания!$C$17) -> 5880 | D8: =D7*(1+Допускания!$C$17) -> 8760 | E8: =E7*(1+Допускания!$C$17) -> 13800 | F8: =F7*(1+Допускания!$C$17) -> 6468 | G8: =G7*(1+Допускания!$C$17) -> 9636 | H8: =H7*(1+Допускания!$C$17) -> 15180 | I8: =I7*(1+Допускания!$C$17) -> 7114.8 | J8: =J7*(1+Допускания!$C$17) -> 10599.6 | K8: =K7*(1+Допускания!$C$17) -> 16698
B10: ПРЕКИ РАЗХОДИ
B11: Сондиране | C11: =C6*Допускания!$C$21*Допускания!$C$8 -> 1008 | D11: =D6*Допускания!$C$21*Допускания!$C$8 -> 1890 | E11: =E6*Допускания!$C$21*Допускания!$C$8 -> 3276 | F11: =F6*Допускания!$D$21*Допускания!$C$8 -> 912 | G11: =G6*Допускания!$D$21*Допускания!$C$8 -> 1710 | H11: =H6*Допускания!$D$21*Допускания!$C$8 -> 2964 | I11: =I6*Допускания!$E$21*Допускания!$C$8 -> 840 | J11: =J6*Допускания!$E$21*Допускания!$C$8 -> 1575 | K11: =K6*Допускания!$E$21*Допускания!$C$8 -> 2730
B12: Обсадни тръби | C12: =C6*Допускания!$C$22 -> 384 | D12: =D6*Допускания!$C$22 -> 720 | E12: =E6*Допускания!$C$22 -> 1248 | F12: =F6*Допускания!$D$22 -> 360 | G12: =G6*Допускания!$D$22 -> 675 | H12: =H6*Допускания!$D$22 -> 1170 | I12: =I6*Допускания!$E$22 -> 360 | J12: =J6*Допускания!$E$22 -> 675 | K12: =K6*Допускания!$E$22 -> 1170
B13: Геофизично проучване | C13: =Допускания!$C$23 -> 50 | D13: =Допускания!$C$23 -> 50 | E13: =Допускания!$C$23 -> 50 | F13: =Допускания!$D$23 -> 50 | G13: =Допускания!$D$23 -> 50 | H13: =Допускания!$D$23 -> 50 | I13: =Допускания!$E$23 -> 50 | J13: =Допускания!$E$23 -> 50 | K13: =Допускания!$E$23 -> 50
B14: Останали фиксирани преки разходи | C14: =Допускания!$C$38*Допускания!$C$24 -> 1210 | D14: =Допускания!$D$38*Допускания!$C$24 -> 1310 | E14: =Допускания!$E$38*Допускания!$C$24 -> 1550 | F14: =Допускания!$C$38*Допускания!$D$24 -> 1137.4 | G14: =Допускания!$D$38*Допускания!$D$24 -> 1231.4 | H14: =Допускания!$E$38*Допускания!$D$24 -> 1457 | I14: =Допускания!$C$38*Допускания!$E$24 -> 1089 | J14: =Допускания!$D$38*Допускания!$E$24 -> 1179 | K14: =Допускания!$E$38*Допускания!$E$24 -> 1395
B15: Общо преки разходи | C15: =SUM(C11:C14) -> 2652 | D15: =SUM(D11:D14) -> 3970 | E15: =SUM(E11:E14) -> 6124 | F15: =SUM(F11:F14) -> 2459.4 | G15: =SUM(G11:G14) -> 3666.4 | H15: =SUM(H11:H14) -> 5641 | I15: =SUM(I11:I14) -> 2339 | J15: =SUM(J11:J14) -> 3479 | K15: =SUM(K11:K14) -> 5345
B17: Брутна печалба преди гаранция | C17: =C7-C15 -> 2248 | D17: =D7-D15 -> 3330 | E17: =E7-E15 -> 5376 | F17: =F7-F15 -> 2930.6 | G17: =G7-G15 -> 4363.6 | H17: =H7-H15 -> 7009 | I17: =I7-I15 -> 3590 | J17: =J7-J15 -> 5354 | K17: =K7-K15 -> 8570
B18: Брутен марж преди гаранция | C18: =IF(C7=0,0,C17/C7) -> 0.45877551 | D18: =IF(D7=0,0,D17/D7) -> 0.45616438 | E18: =IF(E7=0,0,E17/E7) -> 0.46747826 | F18: =IF(F7=0,0,F17/F7) -> 0.54371058 | G18: =IF(G7=0,0,G17/G7) -> 0.5434122 | H18: =IF(H7=0,0,H17/H7) -> 0.55407115 | I18: =IF(I7=0,0,I17/I7) -> 0.6054984 | J18: =IF(J7=0,0,J17/J7) -> 0.60613608 | K18: =IF(K7=0,0,K17/K7) -> 0.61588214
B19: Отчисление в гаранционния фонд | C19: =C7*Допускания!$C$55 -> 392 | D19: =D7*Допускания!$C$55 -> 584 | E19: =E7*Допускания!$C$55 -> 920 | F19: =F7*Допускания!$C$55 -> 431.2 | G19: =G7*Допускания!$C$55 -> 642.4 | H19: =H7*Допускания!$C$55 -> 1012 | I19: =I7*Допускания!$C$55 -> 474.32 | J19: =J7*Допускания!$C$55 -> 706.64 | K19: =K7*Допускания!$C$55 -> 1113.2
B20: Брутна печалба след гаранция | C20: =C17-C19 -> 1856 | D20: =D17-D19 -> 2746 | E20: =E17-E19 -> 4456 | F20: =F17-F19 -> 2499.4 | G20: =G17-G19 -> 3721.2 | H20: =H17-H19 -> 5997 | I20: =I17-I19 -> 3115.68 | J20: =J17-J19 -> 4647.36 | K20: =K17-K19 -> 7456.8
B21: Марж след гаранция | C21: =IF(C7=0,0,C20/C7) -> 0.37877551 | D21: =IF(D7=0,0,D20/D7) -> 0.37616438 | E21: =IF(E7=0,0,E20/E7) -> 0.38747826 | F21: =IF(F7=0,0,F20/F7) -> 0.46371058 | G21: =IF(G7=0,0,G20/G7) -> 0.4634122 | H21: =IF(H7=0,0,H20/H7) -> 0.47407115 | I21: =IF(I7=0,0,I20/I7) -> 0.5254984 | J21: =IF(J7=0,0,J20/J7) -> 0.52613608 | K21: =IF(K7=0,0,K20/K7) -> 0.53588214
B23: Очакван разход по риска на обект | C23: =Допускания!$C$51*C15*Допускания!$C$54+Допускания!$C$51*Допускания!$C$52*Допускания!$C$53*C7 -> 310.994 | D23: =Допускания!$C$51*D15*Допускания!$C$54+Допускания!$C$51*Допускания!$C$52*Допускания!$C$53*D7 -> 464.69 | E23: =Допускания!$C$51*E15*Допускания!$C$54+Допускания!$C$51*Допускания!$C$52*Допускания!$C$53*E7 -> 722.678 | F23: =Допускания!$C$51*F15*Допускания!$C$54+Допускания!$C$51*Допускания!$C$52*Допускания!$C$53*F7 -> 309.1318 | G23: =Допускания!$C$51*G15*Допускания!$C$54+Допускания!$C$51*Допускания!$C$52*Допускания!$C$53*G7 -> 460.7158 | H23: =Допускания!$C$51*H15*Допускания!$C$54+Допускания!$C$51*Допускания!$C$52*Допускания!$C$53*H7 -> 716.077 | I23: =Допускания!$C$51*I15*Допускания!$C$54+Допускания!$C$51*Допускания!$C$52*Допускания!$C$53*I7 -> 313.6685 | J23: =Допускания!$C$51*J15*Допускания!$C$54+Допускания!$C$51*Допускания!$C$52*Допускания!$C$53*J7 -> 466.8965 | K23: =Допускания!$C$51*K15*Допускания!$C$54+Допускания!$C$51*Допускания!$C$52*Допускания!$C$53*K7 -> 725.7575
B24: Покритие на фонда (отчисление / очакван разход) | C24: =IF(C23=0,0,C19/C23) -> 1.2604745 | D24: =IF(D23=0,0,D19/D23) -> 1.2567518 | E24: =IF(E23=0,0,E19/E23) -> 1.2730428 | F24: =IF(F23=0,0,F19/F23) -> 1.3948743 | G24: =IF(G23=0,0,G19/G23) -> 1.394352 | H24: =IF(H23=0,0,H19/H23) -> 1.4132558 | I24: =IF(I23=0,0,I19/I23) -> 1.5121697 | J24: =IF(J23=0,0,J19/J23) -> 1.5134832 | K24: =IF(K23=0,0,K19/K23) -> 1.5338457
B25: Под 100% означава, че фондът не покрива очаквания риск на този пакет.
B27: ПРЕТЕГЛЕНИ СТОЙНОСТИ ЗА ГОДИНАТА (вход за ОПР) | C27: Година 1 | D27: Година 2 | E27: Година 3
B28: Претеглена цена на обект | C28: =C7*Допускания!$F$12+D7*Допускания!$F$13+E7*Допускания!$F$14 -> 8770 | D28: =F7*Допускания!$F$12+G7*Допускания!$F$13+H7*Допускания!$F$14 -> 9647 | E28: =I7*Допускания!$F$12+J7*Допускания!$F$13+K7*Допускания!$F$14 -> 10611.7
B29: Претеглени преки разходи на обект | C29: =C15*Допускания!$F$12+D15*Допускания!$F$13+E15*Допускания!$F$14 -> 4723.9 | D29: =F15*Допускания!$F$12+G15*Допускания!$F$13+H15*Допускания!$F$14 -> 4357.51 | E29: =I15*Допускания!$F$12+J15*Допускания!$F$13+K15*Допускания!$F$14 -> 4132.1
B30: Претеглена брутна печалба на обект | C30: =C17*Допускания!$F$12+D17*Допускания!$F$13+E17*Допускания!$F$14 -> 4046.1 | D30: =F17*Допускания!$F$12+G17*Допускания!$F$13+H17*Допускания!$F$14 -> 5289.49 | E30: =I17*Допускания!$F$12+J17*Допускания!$F$13+K17*Допускания!$F$14 -> 6479.6
B31: Претеглен очакван разход по риска | C31: =C23*Допускания!$F$12+D23*Допускания!$F$13+E23*Допускания!$F$14 -> 554.9858 | D31: =F23*Допускания!$F$12+G23*Допускания!$F$13+H23*Допускания!$F$14 -> 550.09222 | E31: =I23*Допускания!$F$12+J23*Допускания!$F$13+K23*Допускания!$F$14 -> 557.49785
B32: Претеглена дълбочина на обект (м) | C32: =C6*Допускания!$F$12+D6*Допускания!$F$13+E6*Допускания!$F$14 -> 56.55 | D32: =F6*Допускания!$F$12+G6*Допускания!$F$13+H6*Допускания!$F$14 -> 56.55 | E32: =I6*Допускания!$F$12+J6*Допускания!$F$13+K6*Допускания!$F$14 -> 56.55
B33: Претеглен фиксиран разход на обект (без сондиране и обсадни) | C33: =(C13+C14)*Допускания!$F$12+(D13+D14)*Допускания!$F$13+(E13+E14)*Допускания!$F$14 -> 1444 | D33: =(F13+F14)*Допускания!$F$12+(G13+G14)*Допускания!$F$13+(H13+H14)*Допускания!$F$14 -> 1360.36 | E33: =(I13+I14)*Допускания!$F$12+(J13+J14)*Допускания!$F$13+(K13+K14)*Допускания!$F$14 -> 1304.6
B35: Приход от допълнителни продажби на обект | C35: =(Допускания!$C$42*Допускания!$D$42+Допускания!$C$43*Допускания!$D$43+Допускания!$C$44*Допускания!$D$44)*(1+Допускания!$C$16)^0 -> 2092.5 | D35: =(Допускания!$C$42*Допускания!$D$42+Допускания!$C$43*Допускания!$D$43+Допускания!$C$44*Допускания!$D$44)*(1+Допускания!$D$16)^1 -> 2301.75 | E35: =(Допускания!$C$42*Допускания!$D$42+Допускания!$C$43*Допускания!$D$43+Допускания!$C$44*Допускания!$D$44)*(1+Допускания!$E$16)^2 -> 2531.925
B36: Разход по допълнителни продажби на обект | C36: =Допускания!$C$42*Допускания!$E$42+Допускания!$C$43*Допускания!$E$43+Допускания!$C$44*Допускания!$E$44 -> 1198.25 | D36: =Допускания!$C$42*Допускания!$E$42+Допускания!$C$43*Допускания!$E$43+Допускания!$C$44*Допускания!$E$44 -> 1198.25 | E36: =Допускания!$C$42*Допускания!$E$42+Допускания!$C$43*Допускания!$E$43+Допускания!$C$44*Допускания!$E$44 -> 1198.25
B37: Марж от допълнителни продажби на обект | C37: =C35-C36 -> 894.25 | D37: =D35-D36 -> 1103.5 | E37: =E35-E36 -> 1333.675
B39: ПРИНОС НА ЕДИН ОБЕКТ (след гаранционното отчисление)
B40: Общ приход на обект | C40: =C28+C35 -> 10862.5 | D40: =D28+D35 -> 11948.75 | E40: =E28+E35 -> 13143.625
B41: Принос на обект | C41: =C30+C37-C28*Допускания!$C$55 -> 4238.75 | D41: =D30+D37-D28*Допускания!$C$55 -> 5621.23 | E41: =E30+E37-E28*Допускания!$C$55 -> 6964.339
B42: Принос като % от приход | C42: =IF(C40=0,0,C41/C40) -> 0.39021864 | D42: =IF(D40=0,0,D41/D40) -> 0.47044503 | E42: =IF(E40=0,0,E41/E40) -> 0.5298644

Sheet Обеми
B1: Месечни обеми, 36 месеца
B2: Годишният обем се разпределя по сезонния индекс само върху активните месеци.
B4: Месец № | C4: 1 | D4: 2 | E4: 3 | F4: 4 | G4: 5 | H4: 6 | I4: 7 | J4: 8 | K4: 9 | L4: 10 | M4: 11 | N4: 12 | O4: 13 | P4: 14 | Q4: 15 | R4: 16 | S4: 17 | T4: 18 | U4: 19 | V4: 20 | W4: 21 | X4: 22 | Y4: 23 | Z4: 24 | AA4: 25 | AB4: 26 | AC4: 27 | AD4: 28 | AE4: 29 | AF4: 30 | AG4: 31 | AH4: 32 | AI4: 33 | AJ4: 34 | AK4: 35 | AL4: 36 | AN4: Год. 1 | AO4: Год. 2 | AP4: Год. 3
B5: Година | C5: 1 | D5: 1 | E5: 1 | F5: 1 | G5: 1 | H5: 1 | I5: 1 | J5: 1 | K5: 1 | L5: 1 | M5: 1 | N5: 1 | O5: 2 | P5: 2 | Q5: 2 | R5: 2 | S5: 2 | T5: 2 | U5: 2 | V5: 2 | W5: 2 | X5: 2 | Y5: 2 | Z5: 2 | AA5: 3 | AB5: 3 | AC5: 3 | AD5: 3 | AE5: 3 | AF5: 3 | AG5: 3 | AH5: 3 | AI5: 3 | AJ5: 3 | AK5: 3 | AL5: 3
B6: Календарен месец | C6: 1 | D6: 2 | E6: 3 | F6: 4 | G6: 5 | H6: 6 | I6: 7 | J6: 8 | K6: 9 | L6: 10 | M6: 11 | N6: 12 | O6: 1 | P6: 2 | Q6: 3 | R6: 4 | S6: 5 | T6: 6 | U6: 7 | V6: 8 | W6: 9 | X6: 10 | Y6: 11 | Z6: 12 | AA6: 1 | AB6: 2 | AC6: 3 | AD6: 4 | AE6: 5 | AF6: 6 | AG6: 7 | AH6: 8 | AI6: 9 | AJ6: 10 | AK6: 11 | AL6: 12
B7: Сезонен индекс | C7: =INDEX(Допускания!$C$64:$N$64,1,C6) -> 0.3 | D7: =INDEX(Допускания!$C$64:$N$64,1,D6) -> 0.4 | E7: =INDEX(Допускания!$C$64:$N$64,1,E6) -> 0.8 | F7: =INDEX(Допускания!$C$64:$N$64,1,F6) -> 1 | G7: =INDEX(Допускания!$C$64:$N$64,1,G6) -> 1.2 | H7: =INDEX(Допускания!$C$64:$N$64,1,H6) -> 1.4 | I7: =INDEX(Допускания!$C$64:$N$64,1,I6) -> 1.5 | J7: =INDEX(Допускания!$C$64:$N$64,1,J6) -> 2 | ... AL7: =INDEX(Допускания!$C$64:$N$64,1,AL6) -> 0.3
B8: Активен месец (1/0) | C8: =IF(C4>=Допускания!$C$61,1,0) -> 0 | D8: =IF(D4>=Допускания!$C$61,1,0) -> 0 | E8: =IF(E4>=Допускания!$C$61,1,0) -> 0 | F8: =IF(F4>=Допускания!$C$61,1,0) -> 1 | G8: =IF(G4>=Допускания!$C$61,1,0) -> 1 | H8: =IF(H4>=Допускания!$C$61,1,0) -> 1 | I8: =IF(I4>=Допускания!$C$61,1,0) -> 1 | J8: =IF(J4>=Допускания!$C$61,1,0) -> 1 | ... AL8: =IF(AL4>=Допускания!$C$61,1,0) -> 1
B9: Сбор на активните индекси за годината | C9: =IF(C5=1,SUMPRODUCT($C$7:$N$7,$C$8:$N$8),IF(C5=2,SUMPRODUCT($O$7:$Z$7,$O$8:$Z$8),SUMPRODUCT($AA$7:$AL$7,$AA$8:$AL$8))) -> 10.5 | D9: =IF(D5=1,SUMPRODUCT($C$7:$N$7,$C$8:$N$8),IF(D5=2,SUMPRODUCT($O$7:$Z$7,$O$8:$Z$8),SUMPRODUCT($AA$7:$AL$7,$AA$8:$AL$8))) -> 10.5 | E9: =IF(E5=1,SUMPRODUCT($C$7:$N$7,$C$8:$N$8),IF(E5=2,SUMPRODUCT($O$7:$Z$7,$O$8:$Z$8),SUMPRODUCT($AA$7:$AL$7,$AA$8:$AL$8))) -> 10.5 | F9: =IF(F5=1,SUMPRODUCT($C$7:$N$7,$C$8:$N$8),IF(F5=2,SUMPRODUCT($O$7:$Z$7,$O$8:$Z$8),SUMPRODUCT($AA$7:$AL$7,$AA$8:$AL$8))) -> 10.5 | G9: =IF(G5=1,SUMPRODUCT($C$7:$N$7,$C$8:$N$8),IF(G5=2,SUMPRODUCT($O$7:$Z$7,$O$8:$Z$8),SUMPRODUCT($AA$7:$AL$7,$AA$8:$AL$8))) -> 10.5 | H9: =IF(H5=1,SUMPRODUCT($C$7:$N$7,$C$8:$N$8),IF(H5=2,SUMPRODUCT($O$7:$Z$7,$O$8:$Z$8),SUMPRODUCT($AA$7:$AL$7,$AA$8:$AL$8))) -> 10.5 | I9: =IF(I5=1,SUMPRODUCT($C$7:$N$7,$C$8:$N$8),IF(I5=2,SUMPRODUCT($O$7:$Z$7,$O$8:$Z$8),SUMPRODUCT($AA$7:$AL$7,$AA$8:$AL$8))) -> 10.5 | J9: =IF(J5=1,SUMPRODUCT($C$7:$N$7,$C$8:$N$8),IF(J5=2,SUMPRODUCT($O$7:$Z$7,$O$8:$Z$8),SUMPRODUCT($AA$7:$AL$7,$AA$8:$AL$8))) -> 10.5 | ... AL9: =IF(AL5=1,SUMPRODUCT($C$7:$N$7,$C$8:$N$8),IF(AL5=2,SUMPRODUCT($O$7:$Z$7,$O$8:$Z$8),SUMPRODUCT($AA$7:$AL$7,$AA$8:$AL$8))) -> 12
B10: Годишен обем (с множител на сценария) | C10: =IF(C5=1,Допускания!$C$60,IF(C5=2,Допускания!$D$60,Допускания!$E$60))*Допускания!$C$6 -> 26 | D10: =IF(D5=1,Допускания!$C$60,IF(D5=2,Допускания!$D$60,Допускания!$E$60))*Допускания!$C$6 -> 26 | E10: =IF(E5=1,Допускания!$C$60,IF(E5=2,Допускания!$D$60,Допускания!$E$60))*Допускания!$C$6 -> 26 | F10: =IF(F5=1,Допускания!$C$60,IF(F5=2,Допускания!$D$60,Допускания!$E$60))*Допускания!$C$6 -> 26 | G10: =IF(G5=1,Допускания!$C$60,IF(G5=2,Допускания!$D$60,Допускания!$E$60))*Допускания!$C$6 -> 26 | H10: =IF(H5=1,Допускания!$C$60,IF(H5=2,Допускания!$D$60,Допускания!$E$60))*Допускания!$C$6 -> 26 | I10: =IF(I5=1,Допускания!$C$60,IF(I5=2,Допускания!$D$60,Допускания!$E$60))*Допускания!$C$6 -> 26 | J10: =IF(J5=1,Допускания!$C$60,IF(J5=2,Допускания!$D$60,Допускания!$E$60))*Допускания!$C$6 -> 26 | ... AL10: =IF(AL5=1,Допускания!$C$60,IF(AL5=2,Допускания!$D$60,Допускания!$E$60))*Допускания!$C$6 -> 50
B11: ОБЕКТИ ПРЕЗ МЕСЕЦА | C11: =IF(C9=0,0,C10*C7*C8/C9) -> 0 | D11: =IF(D9=0,0,D10*D7*D8/D9) -> 0 | E11: =IF(E9=0,0,E10*E7*E8/E9) -> 0 | F11: =IF(F9=0,0,F10*F7*F8/F9) -> 2.4761905 | G11: =IF(G9=0,0,G10*G7*G8/G9) -> 2.9714286 | H11: =IF(H9=0,0,H10*H7*H8/H9) -> 3.4666667 | I11: =IF(I9=0,0,I10*I7*I8/I9) -> 3.7142857 | J11: =IF(J9=0,0,J10*J7*J8/J9) -> 4.952381 | ... AL11: =IF(AL9=0,0,AL10*AL7*AL8/AL9) -> 1.25 | AN11: =SUM(C11:N11) -> 26 | AO11: =SUM(O11:Z11) -> 35 | AP11: =SUM(AA11:AL11) -> 50
B12: Линейни метри сондиране | C12: =C11*IF(C5=1,Пакети!$C$32,IF(C5=2,Пакети!$D$32,Пакети!$E$32)) -> 0 | D12: =D11*IF(D5=1,Пакети!$C$32,IF(D5=2,Пакети!$D$32,Пакети!$E$32)) -> 0 | E12: =E11*IF(E5=1,Пакети!$C$32,IF(E5=2,Пакети!$D$32,Пакети!$E$32)) -> 0 | F12: =F11*IF(F5=1,Пакети!$C$32,IF(F5=2,Пакети!$D$32,Пакети!$E$32)) -> 140.02857 | G12: =G11*IF(G5=1,Пакети!$C$32,IF(G5=2,Пакети!$D$32,Пакети!$E$32)) -> 168.03429 | H12: =H11*IF(H5=1,Пакети!$C$32,IF(H5=2,Пакети!$D$32,Пакети!$E$32)) -> 196.04 | I12: =I11*IF(I5=1,Пакети!$C$32,IF(I5=2,Пакети!$D$32,Пакети!$E$32)) -> 210.04286 | J12: =J11*IF(J5=1,Пакети!$C$32,IF(J5=2,Пакети!$D$32,Пакети!$E$32)) -> 280.05714 | ... AL12: =AL11*IF(AL5=1,Пакети!$C$32,IF(AL5=2,Пакети!$D$32,Пакети!$E$32)) -> 70.6875 | AN12: =SUM(C12:N12) -> 1470.3 | AO12: =SUM(O12:Z12) -> 1979.25 | AP12: =SUM(AA12:AL12) -> 2827.5
B13: Запитвания, необходими при отказ на рискови обекти | C13: =C11/(1-Допускания!$C$56) -> 0 | D13: =D11/(1-Допускания!$C$56) -> 0 | E13: =E11/(1-Допускания!$C$56) -> 0 | F13: =F11/(1-Допускания!$C$56) -> 3.3015873 | G13: =G11/(1-Допускания!$C$56) -> 3.9619048 | H13: =H11/(1-Допускания!$C$56) -> 4.6222222 | I13: =I11/(1-Допускания!$C$56) -> 4.952381 | J13: =J11/(1-Допускания!$C$56) -> 6.6031746 | ... AL13: =AL11/(1-Допускания!$C$56) -> 1.6666667 | AN13: =SUM(C13:N13) -> 34.666667 | AO13: =SUM(O13:Z13) -> 46.666667 | AP13: =SUM(AA13:AL13) -> 66.666667

Sheet ОПР
B1: Отчет за приходите и разходите, месечно
B2: Всички суми в EUR без ДДС. Колони AN–AP съдържат годишните суми.
B4: Месец № | C4: =Обеми!C4 -> 1 | D4: =Обеми!D4 -> 2 | E4: =Обеми!E4 -> 3 | F4: =Обеми!F4 -> 4 | G4: =Обеми!G4 -> 5 | H4: =Обеми!H4 -> 6 | I4: =Обеми!I4 -> 7 | J4: =Обеми!J4 -> 8 | ... AL4: =Обеми!AL4 -> 36 | AN4: Година 1 | AO4: Година 2 | AP4: Година 3
B5: ПРИХОДИ
B6: Приход от пакети | C6: =Обеми!C11*IF(Обеми!C$5=1,Пакети!$C$28,IF(Обеми!C$5=2,Пакети!$D$28,Пакети!$E$28)) -> 0 | D6: =Обеми!D11*IF(Обеми!D$5=1,Пакети!$C$28,IF(Обеми!D$5=2,Пакети!$D$28,Пакети!$E$28)) -> 0 | E6: =Обеми!E11*IF(Обеми!E$5=1,Пакети!$C$28,IF(Обеми!E$5=2,Пакети!$D$28,Пакети!$E$28)) -> 0 | F6: =Обеми!F11*IF(Обеми!F$5=1,Пакети!$C$28,IF(Обеми!F$5=2,Пакети!$D$28,Пакети!$E$28)) -> 21716.19 | G6: =Обеми!G11*IF(Обеми!G$5=1,Пакети!$C$28,IF(Обеми!G$5=2,Пакети!$D$28,Пакети!$E$28)) -> 26059.429 | H6: =Обеми!H11*IF(Обеми!H$5=1,Пакети!$C$28,IF(Обеми!H$5=2,Пакети!$D$28,Пакети!$E$28)) -> 30402.667 | I6: =Обеми!I11*IF(Обеми!I$5=1,Пакети!$C$28,IF(Обеми!I$5=2,Пакети!$D$28,Пакети!$E$28)) -> 32574.286 | J6: =Обеми!J11*IF(Обеми!J$5=1,Пакети!$C$28,IF(Обеми!J$5=2,Пакети!$D$28,Пакети!$E$28)) -> 43432.381 | ... AL6: =Обеми!AL11*IF(Обеми!AL$5=1,Пакети!$C$28,IF(Обеми!AL$5=2,Пакети!$D$28,Пакети!$E$28)) -> 13264.625 | AN6: =SUM(C6:N6) -> 228020 | AO6: =SUM(O6:Z6) -> 337645 | AP6: =SUM(AA6:AL6) -> 530585
B7: Приход от допълнителни продажби | C7: =Обеми!C11*IF(Обеми!C$5=1,Пакети!$C$35,IF(Обеми!C$5=2,Пакети!$D$35,Пакети!$E$35)) -> 0 | D7: =Обеми!D11*IF(Обеми!D$5=1,Пакети!$C$35,IF(Обеми!D$5=2,Пакети!$D$35,Пакети!$E$35)) -> 0 | E7: =Обеми!E11*IF(Обеми!E$5=1,Пакети!$C$35,IF(Обеми!E$5=2,Пакети!$D$35,Пакети!$E$35)) -> 0 | F7: =Обеми!F11*IF(Обеми!F$5=1,Пакети!$C$35,IF(Обеми!F$5=2,Пакети!$D$35,Пакети!$E$35)) -> 5181.4286 | G7: =Обеми!G11*IF(Обеми!G$5=1,Пакети!$C$35,IF(Обеми!G$5=2,Пакети!$D$35,Пакети!$E$35)) -> 6217.7143 | H7: =Обеми!H11*IF(Обеми!H$5=1,Пакети!$C$35,IF(Обеми!H$5=2,Пакети!$D$35,Пакети!$E$35)) -> 7254 | I7: =Обеми!I11*IF(Обеми!I$5=1,Пакети!$C$35,IF(Обеми!I$5=2,Пакети!$D$35,Пакети!$E$35)) -> 7772.1429 | J7: =Обеми!J11*IF(Обеми!J$5=1,Пакети!$C$35,IF(Обеми!J$5=2,Пакети!$D$35,Пакети!$E$35)) -> 10362.857 | ... AL7: =Обеми!AL11*IF(Обеми!AL$5=1,Пакети!$C$35,IF(Обеми!AL$5=2,Пакети!$D$35,Пакети!$E$35)) -> 3164.9062 | AN7: =SUM(C7:N7) -> 54405 | AO7: =SUM(O7:Z7) -> 80561.25 | AP7: =SUM(AA7:AL7) -> 126596.25
B8: Активни абонати за мониторинг (брой) | C8: =0*(1-Допускания!$C$48)+Обеми!C11*Допускания!$C$45 -> 0 | D8: =C8*(1-Допускания!$C$48)+Обеми!D11*Допускания!$C$45 -> 0 | E8: =D8*(1-Допускания!$C$48)+Обеми!E11*Допускания!$C$45 -> 0 | F8: =E8*(1-Допускания!$C$48)+Обеми!F11*Допускания!$C$45 -> 0.24761905 | G8: =F8*(1-Допускания!$C$48)+Обеми!G11*Допускания!$C$45 -> 0.54278095 | H8: =G8*(1-Допускания!$C$48)+Обеми!H11*Допускания!$C$45 -> 0.88510537 | I8: =H8*(1-Допускания!$C$48)+Обеми!I11*Допускания!$C$45 -> 1.2494531 | J8: =I8*(1-Допускания!$C$48)+Обеми!J11*Допускания!$C$45 -> 1.7346956 | K8: =J8*(1-Допускания!$C$48)+Обеми!K11*Допускания!$C$45 -> 2.0427228 | ... AL8: =AK8*(1-Допускания!$C$48)+Обеми!AL11*Допускания!$C$45 -> 9.9183918
B9: Приход от абонаменти | C9: =C8*Допускания!$C$46 -> 0 | D9: =D8*Допускания!$C$46 -> 0 | E9: =E8*Допускания!$C$46 -> 0 | F9: =F8*Допускания!$C$46 -> 13.619048 | G9: =G8*Допускания!$C$46 -> 29.852952 | H9: =H8*Допускания!$C$46 -> 48.680795 | I9: =I8*Допускания!$C$46 -> 68.71992 | J9: =J8*Допускания!$C$46 -> 95.408256 | ... AL9: =AL8*Допускания!$C$46 -> 545.51155 | AN9: =SUM(C9:N9) -> 767.97628 | AO9: =SUM(O9:Z9) -> 2723.4071 | AP9: =SUM(AA9:AL9) -> 5177.6847
B10: ОБЩО ПРИХОДИ | C10: =SUM(C6:C9)-C8*0 -> 0 | D10: =SUM(D6:D9)-D8*0 -> 0 | E10: =SUM(E6:E9)-E8*0 -> 0 | F10: =SUM(F6:F9)-F8*0 -> 26911.486 | G10: =SUM(G6:G9)-G8*0 -> 32307.539 | H10: =SUM(H6:H9)-H8*0 -> 37706.233 | I10: =SUM(I6:I9)-I8*0 -> 40416.398 | J10: =SUM(J6:J9)-J8*0 -> 53892.381 | ... AL10: =SUM(AL6:AL9)-AL8*0 -> 16984.961 | AN10: =SUM(C10:N10) -> 283206.94 | AO10: =SUM(O10:Z10) -> 420979.17 | AP10: =SUM(AA10:AL10) -> 662453.07
B12: ПРЕКИ РАЗХОДИ
B13: Сондиране (подизпълнител) | C13: =Обеми!C12*IF(Обеми!C$5=1,Допускания!$C$21,IF(Обеми!C$5=2,Допускания!$D$21,Допускания!$E$21))*Допускания!$C$8 -> 0 | D13: =Обеми!D12*IF(Обеми!D$5=1,Допускания!$C$21,IF(Обеми!D$5=2,Допускания!$D$21,Допускания!$E$21))*Допускания!$C$8 -> 0 | E13: =Обеми!E12*IF(Обеми!E$5=1,Допускания!$C$21,IF(Обеми!E$5=2,Допускания!$D$21,Допускания!$E$21))*Допускания!$C$8 -> 0 | F13: =Обеми!F12*IF(Обеми!F$5=1,Допускания!$C$21,IF(Обеми!F$5=2,Допускания!$D$21,Допускания!$E$21))*Допускания!$C$8 -> 5881.2 | G13: =Обеми!G12*IF(Обеми!G$5=1,Допускания!$C$21,IF(Обеми!G$5=2,Допускания!$D$21,Допускания!$E$21))*Допускания!$C$8 -> 7057.44 | H13: =Обеми!H12*IF(Обеми!H$5=1,Допускания!$C$21,IF(Обеми!H$5=2,Допускания!$D$21,Допускания!$E$21))*Допускания!$C$8 -> 8233.68 | I13: =Обеми!I12*IF(Обеми!I$5=1,Допускания!$C$21,IF(Обеми!I$5=2,Допускания!$D$21,Допускания!$E$21))*Допускания!$C$8 -> 8821.8 | J13: =Обеми!J12*IF(Обеми!J$5=1,Допускания!$C$21,IF(Обеми!J$5=2,Допускания!$D$21,Допускания!$E$21))*Допускания!$C$8 -> 11762.4 | ... AL13: =Обеми!AL12*IF(Обеми!AL$5=1,Допускания!$C$21,IF(Обеми!AL$5=2,Допускания!$D$21,Допускания!$E$21))*Допускания!$C$8 -> 2474.0625 | AN13: =SUM(C13:N13) -> 61752.6 | AO13: =SUM(O13:Z13) -> 75211.5 | AP13: =SUM(AA13:AL13) -> 98962.5
B14: Обсадни тръби | C14: =Обеми!C12*IF(Обеми!C$5=1,Допускания!$C$22,IF(Обеми!C$5=2,Допускания!$D$22,Допускания!$E$22)) -> 0 | D14: =Обеми!D12*IF(Обеми!D$5=1,Допускания!$C$22,IF(Обеми!D$5=2,Допускания!$D$22,Допускания!$E$22)) -> 0 | E14: =Обеми!E12*IF(Обеми!E$5=1,Допускания!$C$22,IF(Обеми!E$5=2,Допускания!$D$22,Допускания!$E$22)) -> 0 | F14: =Обеми!F12*IF(Обеми!F$5=1,Допускания!$C$22,IF(Обеми!F$5=2,Допускания!$D$22,Допускания!$E$22)) -> 2240.4571 | G14: =Обеми!G12*IF(Обеми!G$5=1,Допускания!$C$22,IF(Обеми!G$5=2,Допускания!$D$22,Допускания!$E$22)) -> 2688.5486 | H14: =Обеми!H12*IF(Обеми!H$5=1,Допускания!$C$22,IF(Обеми!H$5=2,Допускания!$D$22,Допускания!$E$22)) -> 3136.64 | I14: =Обеми!I12*IF(Обеми!I$5=1,Допускания!$C$22,IF(Обеми!I$5=2,Допускания!$D$22,Допускания!$E$22)) -> 3360.6857 | J14: =Обеми!J12*IF(Обеми!J$5=1,Допускания!$C$22,IF(Обеми!J$5=2,Допускания!$D$22,Допускания!$E$22)) -> 4480.9143 | ... AL14: =Обеми!AL12*IF(Обеми!AL$5=1,Допускания!$C$22,IF(Обеми!AL$5=2,Допускания!$D$22,Допускания!$E$22)) -> 1060.3125 | AN14: =SUM(C14:N14) -> 23524.8 | AO14: =SUM(O14:Z14) -> 29688.75 | AP14: =SUM(AA14:AL14) -> 42412.5
B15: Фиксирани преки разходи и геофизика | C15: =Обеми!C11*IF(Обеми!C$5=1,Пакети!$C$33,IF(Обеми!C$5=2,Пакети!$D$33,Пакети!$E$33)) -> 0 | D15: =Обеми!D11*IF(Обеми!D$5=1,Пакети!$C$33,IF(Обеми!D$5=2,Пакети!$D$33,Пакети!$E$33)) -> 0 | E15: =Обеми!E11*IF(Обеми!E$5=1,Пакети!$C$33,IF(Обеми!E$5=2,Пакети!$D$33,Пакети!$E$33)) -> 0 | F15: =Обеми!F11*IF(Обеми!F$5=1,Пакети!$C$33,IF(Обеми!F$5=2,Пакети!$D$33,Пакети!$E$33)) -> 3575.619 | G15: =Обеми!G11*IF(Обеми!G$5=1,Пакети!$C$33,IF(Обеми!G$5=2,Пакети!$D$33,Пакети!$E$33)) -> 4290.7429 | H15: =Обеми!H11*IF(Обеми!H$5=1,Пакети!$C$33,IF(Обеми!H$5=2,Пакети!$D$33,Пакети!$E$33)) -> 5005.8667 | I15: =Обеми!I11*IF(Обеми!I$5=1,Пакети!$C$33,IF(Обеми!I$5=2,Пакети!$D$33,Пакети!$E$33)) -> 5363.4286 | J15: =Обеми!J11*IF(Обеми!J$5=1,Пакети!$C$33,IF(Обеми!J$5=2,Пакети!$D$33,Пакети!$E$33)) -> 7151.2381 | ... AL15: =Обеми!AL11*IF(Обеми!AL$5=1,Пакети!$C$33,IF(Обеми!AL$5=2,Пакети!$D$33,Пакети!$E$33)) -> 1630.75 | AN15: =SUM(C15:N15) -> 37544 | AO15: =SUM(O15:Z15) -> 47612.6 | AP15: =SUM(AA15:AL15) -> 65230
B16: Разходи по допълнителни продажби | C16: =Обеми!C11*IF(Обеми!C$5=1,Пакети!$C$36,IF(Обеми!C$5=2,Пакети!$D$36,Пакети!$E$36)) -> 0 | D16: =Обеми!D11*IF(Обеми!D$5=1,Пакети!$C$36,IF(Обеми!D$5=2,Пакети!$D$36,Пакети!$E$36)) -> 0 | E16: =Обеми!E11*IF(Обеми!E$5=1,Пакети!$C$36,IF(Обеми!E$5=2,Пакети!$D$36,Пакети!$E$36)) -> 0 | F16: =Обеми!F11*IF(Обеми!F$5=1,Пакети!$C$36,IF(Обеми!F$5=2,Пакети!$D$36,Пакети!$E$36)) -> 2967.0952 | G16: =Обеми!G11*IF(Обеми!G$5=1,Пакети!$C$36,IF(Обеми!G$5=2,Пакети!$D$36,Пакети!$E$36)) -> 3560.5143 | H16: =Обеми!H11*IF(Обеми!H$5=1,Пакети!$C$36,IF(Обеми!H$5=2,Пакети!$D$36,Пакети!$E$36)) -> 4153.9333 | I16: =Обеми!I11*IF(Обеми!I$5=1,Пакети!$C$36,IF(Обеми!I$5=2,Пакети!$D$36,Пакети!$E$36)) -> 4450.6429 | J16: =Обеми!J11*IF(Обеми!J$5=1,Пакети!$C$36,IF(Обеми!J$5=2,Пакети!$D$36,Пакети!$E$36)) -> 5934.1905 | ... AL16: =Обеми!AL11*IF(Обеми!AL$5=1,Пакети!$C$36,IF(Обеми!AL$5=2,Пакети!$D$36,Пакети!$E$36)) -> 1497.8125 | AN16: =SUM(C16:N16) -> 31154.5 | AO16: =SUM(O16:Z16) -> 41938.75 | AP16: =SUM(AA16:AL16) -> 59912.5
B17: Разходи по абонаментите | C17: =C8*Допускания!$C$47 -> 0 | D17: =D8*Допускания!$C$47 -> 0 | E17: =E8*Допускания!$C$47 -> 0 | F17: =F8*Допускания!$C$47 -> 4.4571429 | G17: =G8*Допускания!$C$47 -> 9.7700571 | H17: =H8*Допускания!$C$47 -> 15.931897 | I17: =I8*Допускания!$C$47 -> 22.490156 | J17: =J8*Допускания!$C$47 -> 31.22452 | ... AL17: =AL8*Допускания!$C$47 -> 178.53105 | AN17: =SUM(C17:N17) -> 251.33769 | AO17: =SUM(O17:Z17) -> 891.29688 | AP17: =SUM(AA17:AL17) -> 1694.515
B18: Отчисление в гаранционния фонд | C18: =C6*Допускания!$C$55 -> 0 | D18: =D6*Допускания!$C$55 -> 0 | E18: =E6*Допускания!$C$55 -> 0 | F18: =F6*Допускания!$C$55 -> 1737.2952 | G18: =G6*Допускания!$C$55 -> 2084.7543 | H18: =H6*Допускания!$C$55 -> 2432.2133 | I18: =I6*Допускания!$C$55 -> 2605.9429 | J18: =J6*Допускания!$C$55 -> 3474.5905 | ... AL18: =AL6*Допускания!$C$55 -> 1061.17 | AN18: =SUM(C18:N18) -> 18241.6 | AO18: =SUM(O18:Z18) -> 27011.6 | AP18: =SUM(AA18:AL18) -> 42446.8
B19: ОБЩО ПРЕКИ РАЗХОДИ | C19: =SUM(C13:C18) -> 0 | D19: =SUM(D13:D18) -> 0 | E19: =SUM(E13:E18) -> 0 | F19: =SUM(F13:F18) -> 16406.124 | G19: =SUM(G13:G18) -> 19691.77 | H19: =SUM(H13:H18) -> 22978.265 | I19: =SUM(I13:I18) -> 24624.99 | J19: =SUM(J13:J18) -> 32834.558 | ... AL19: =SUM(AL13:AL18) -> 7902.6386 | AN19: =SUM(C19:N19) -> 172468.84 | AO19: =SUM(O19:Z19) -> 222354.5 | AP19: =SUM(AA19:AL19) -> 310658.81
B21: БРУТНА ПЕЧАЛБА | C21: =C10-C19 -> 0 | D21: =D10-D19 -> 0 | E21: =E10-E19 -> 0 | F21: =F10-F19 -> 10505.362 | G21: =G10-G19 -> 12615.769 | H21: =H10-H19 -> 14727.967 | I21: =I10-I19 -> 15791.408 | J21: =J10-J19 -> 21057.823 | ... AL21: =AL10-AL19 -> 9082.3226 | AN21: =SUM(C21:N21) -> 110738.1 | AO21: =SUM(O21:Z21) -> 198624.68 | AP21: =SUM(AA21:AL21) -> 351794.26
B22: Брутен марж | C22: =IF(C10=0,0,C21/C10) -> 0 | D22: =IF(D10=0,0,D21/D10) -> 0 | E22: =IF(E10=0,0,E21/E10) -> 0 | F22: =IF(F10=0,0,F21/F10) -> 0.39036722 | G22: =IF(G10=0,0,G21/G10) -> 0.39048993 | H22: =IF(H10=0,0,H21/H10) -> 0.39059769 | I22: =IF(I10=0,0,I21/I10) -> 0.39071784 | J22: =IF(J10=0,0,J21/J10) -> 0.39073841 | ... AL22: =IF(AL10=0,0,AL21/AL10) -> 0.53472731 | AN22: =IF(AN10=0,0,AN21/AN10) -> 0.39101479 | AO22: =IF(AO10=0,0,AO21/AO10) -> 0.47181592 | AP22: =IF(AP10=0,0,AP21/AP10) -> 0.53104782
B24: ОПЕРАТИВНИ РАЗХОДИ
B25: Възнаграждения (бруто) | C25: =IF(Обеми!C8=0,0,IF(Обеми!C$5=1,Допускания!$C$73,IF(Обеми!C$5=2,Допускания!$D$73,Допускания!$E$73))) -> 0 | D25: =IF(Обеми!D8=0,0,IF(Обеми!D$5=1,Допускания!$C$73,IF(Обеми!D$5=2,Допускания!$D$73,Допускания!$E$73))) -> 0 | E25: =IF(Обеми!E8=0,0,IF(Обеми!E$5=1,Допускания!$C$73,IF(Обеми!E$5=2,Допускания!$D$73,Допускания!$E$73))) -> 0 | F25: =IF(Обеми!F8=0,0,IF(Обеми!F$5=1,Допускания!$C$73,IF(Обеми!F$5=2,Допускания!$D$73,Допускания!$E$73))) -> 2500 | G25: =IF(Обеми!G8=0,0,IF(Обеми!G$5=1,Допускания!$C$73,IF(Обеми!G$5=2,Допускания!$D$73,Допускания!$E$73))) -> 2500 | H25: =IF(Обеми!H8=0,0,IF(Обеми!H$5=1,Допускания!$C$73,IF(Обеми!H$5=2,Допускания!$D$73,Допускания!$E$73))) -> 2500 | I25: =IF(Обеми!I8=0,0,IF(Обеми!I$5=1,Допускания!$C$73,IF(Обеми!I$5=2,Допускания!$D$73,Допускания!$E$73))) -> 2500 | J25: =IF(Обеми!J8=0,0,IF(Обеми!J$5=1,Допускания!$C$73,IF(Обеми!J$5=2,Допускания!$D$73,Допускания!$E$73))) -> 2500 | ... AL25: =IF(Обеми!AL8=0,0,IF(Обеми!AL$5=1,Допускания!$C$73,IF(Обеми!AL$5=2,Допускания!$D$73,Допускания!$E$73))) -> 10100 | AN25: =SUM(C25:N25) -> 22500 | AO25: =SUM(O25:Z25) -> 60000 | AP25: =SUM(AA25:AL25) -> 121200
B26: Осигуровки за сметка на работодателя | C26: =C25*IF(Обеми!C$5=1,Допускания!$C$74,IF(Обеми!C$5=2,Допускания!$D$74,Допускания!$E$74)) -> 0 | D26: =D25*IF(Обеми!D$5=1,Допускания!$C$74,IF(Обеми!D$5=2,Допускания!$D$74,Допускания!$E$74)) -> 0 | E26: =E25*IF(Обеми!E$5=1,Допускания!$C$74,IF(Обеми!E$5=2,Допускания!$D$74,Допускания!$E$74)) -> 0 | F26: =F25*IF(Обеми!F$5=1,Допускания!$C$74,IF(Обеми!F$5=2,Допускания!$D$74,Допускания!$E$74)) -> 475 | G26: =G25*IF(Обеми!G$5=1,Допускания!$C$74,IF(Обеми!G$5=2,Допускания!$D$74,Допускания!$E$74)) -> 475 | H26: =H25*IF(Обеми!H$5=1,Допускания!$C$74,IF(Обеми!H$5=2,Допускания!$D$74,Допускания!$E$74)) -> 475 | I26: =I25*IF(Обеми!I$5=1,Допускания!$C$74,IF(Обеми!I$5=2,Допускания!$D$74,Допускания!$E$74)) -> 475 | J26: =J25*IF(Обеми!J$5=1,Допускания!$C$74,IF(Обеми!J$5=2,Допускания!$D$74,Допускания!$E$74)) -> 475 | ... AL26: =AL25*IF(Обеми!AL$5=1,Допускания!$C$74,IF(Обеми!AL$5=2,Допускания!$D$74,Допускания!$E$74)) -> 1919 | AN26: =SUM(C26:N26) -> 4275 | AO26: =SUM(O26:Z26) -> 11400 | AP26: =SUM(AA26:AL26) -> 23028
B27: Други оперативни разходи | C27: =IF(Обеми!C$5=1,Допускания!$C$82,IF(Обеми!C$5=2,Допускания!$D$82,Допускания!$E$82)) -> 3030 | D27: =IF(Обеми!D$5=1,Допускания!$C$82,IF(Обеми!D$5=2,Допускания!$D$82,Допускания!$E$82)) -> 3030 | E27: =IF(Обеми!E$5=1,Допускания!$C$82,IF(Обеми!E$5=2,Допускания!$D$82,Допускания!$E$82)) -> 3030 | F27: =IF(Обеми!F$5=1,Допускания!$C$82,IF(Обеми!F$5=2,Допускания!$D$82,Допускания!$E$82)) -> 3030 | G27: =IF(Обеми!G$5=1,Допускания!$C$82,IF(Обеми!G$5=2,Допускания!$D$82,Допускания!$E$82)) -> 3030 | H27: =IF(Обеми!H$5=1,Допускания!$C$82,IF(Обеми!H$5=2,Допускания!$D$82,Допускания!$E$82)) -> 3030 | I27: =IF(Обеми!I$5=1,Допускания!$C$82,IF(Обеми!I$5=2,Допускания!$D$82,Допускания!$E$82)) -> 3030 | J27: =IF(Обеми!J$5=1,Допускания!$C$82,IF(Обеми!J$5=2,Допускания!$D$82,Допускания!$E$82)) -> 3030 | ... AL27: =IF(Обеми!AL$5=1,Допускания!$C$82,IF(Обеми!AL$5=2,Допускания!$D$82,Допускания!$E$82)) -> 5830 | AN27: =SUM(C27:N27) -> 36360 | AO27: =SUM(O27:Z27) -> 52800 | AP27: =SUM(AA27:AL27) -> 69960
B28: ОБЩО ОПЕРАТИВНИ РАЗХОДИ | C28: =C25+C26+C27 -> 3030 | D28: =D25+D26+D27 -> 3030 | E28: =E25+E26+E27 -> 3030 | F28: =F25+F26+F27 -> 6005 | G28: =G25+G26+G27 -> 6005 | H28: =H25+H26+H27 -> 6005 | I28: =I25+I26+I27 -> 6005 | J28: =J25+J26+J27 -> 6005 | ... AL28: =AL25+AL26+AL27 -> 17849 | AN28: =SUM(C28:N28) -> 63135 | AO28: =SUM(O28:Z28) -> 124200 | AP28: =SUM(AA28:AL28) -> 214188
B30: EBITDA | C30: =C21-C28 -> -3030 | D30: =D21-D28 -> -3030 | E30: =E21-E28 -> -3030 | F30: =F21-F28 -> 4500.3619 | G30: =G21-G28 -> 6610.7685 | H30: =H21-H28 -> 8722.9673 | I30: =I21-I28 -> 9786.4078 | J30: =J21-J28 -> 15052.823 | ... AL30: =AL21-AL28 -> -8766.6774 | AN30: =SUM(C30:N30) -> 47603.102 | AO30: =SUM(O30:Z30) -> 74424.677 | AP30: =SUM(AA30:AL30) -> 137606.26
B31: EBITDA марж | C31: =IF(C10=0,0,C30/C10) -> 0 | D31: =IF(D10=0,0,D30/D10) -> 0 | E31: =IF(E10=0,0,E30/E10) -> 0 | F31: =IF(F10=0,0,F30/F10) -> 0.1672283 | G31: =IF(G10=0,0,G30/G10) -> 0.20462 | H31: =IF(H10=0,0,H30/H10) -> 0.2313402 | I31: =IF(I10=0,0,I30/I10) -> 0.24213953 | J31: =IF(J10=0,0,J30/J10) -> 0.27931264 | ... AL31: =IF(AL10=0,0,AL30/AL10) -> -0.5161435 | AN31: =IF(AN10=0,0,AN30/AN10) -> 0.16808593 | AO31: =IF(AO10=0,0,AO30/AO10) -> 0.17678945 | AP31: =IF(AP10=0,0,AP30/AP10) -> 0.20772227
B32: Амортизация | C32: =IF(Обеми!C4<=12,Допускания!$C$91/Допускания!$C$92/12,IF(Обеми!C4<=24,(Допускания!$C$91+Допускания!$D$91)/Допускания!$C$92/12,(Допускания!$C$91+Допускания!$D$91+Допускания!$E$91)/Допускания!$C$92/12)) -> 95 | D32: =IF(Обеми!D4<=12,Допускания!$C$91/Допускания!$C$92/12,IF(Обеми!D4<=24,(Допускания!$C$91+Допускания!$D$91)/Допускания!$C$92/12,(Допускания!$C$91+Допускания!$D$91+Допускания!$E$91)/Допускания!$C$92/12)) -> 95 | E32: =IF(Обеми!E4<=12,Допускания!$C$91/Допускания!$C$92/12,IF(Обеми!E4<=24,(Допускания!$C$91+Допускания!$D$91)/Допускания!$C$92/12,(Допускания!$C$91+Допускания!$D$91+Допускания!$E$91)/Допускания!$C$92/12)) -> 95 | F32: =IF(Обеми!F4<=12,Допускания!$C$91/Допускания!$C$92/12,IF(Обеми!F4<=24,(Допускания!$C$91+Допускания!$D$91)/Допускания!$C$92/12,(Допускания!$C$91+Допускания!$D$91+Допускания!$E$91)/Допускания!$C$92/12)) -> 95 | G32: =IF(Обеми!G4<=12,Допускания!$C$91/Допускания!$C$92/12,IF(Обеми!G4<=24,(Допускания!$C$91+Допускания!$D$91)/Допускания!$C$92/12,(Допускания!$C$91+Допускания!$D$91+Допускания!$E$91)/Допускания!$C$92/12)) -> 95 | H32: =IF(Обеми!H4<=12,Допускания!$C$91/Допускания!$C$92/12,IF(Обеми!H4<=24,(Допускания!$C$91+Допускания!$D$91)/Допускания!$C$92/12,(Допускания!$C$91+Допускания!$D$91+Допускания!$E$91)/Допускания!$C$92/12)) -> 95 | I32: =IF(Обеми!I4<=12,Допускания!$C$91/Допускания!$C$92/12,IF(Обеми!I4<=24,(Допускания!$C$91+Допускания!$D$91)/Допускания!$C$92/12,(Допускания!$C$91+Допускания!$D$91+Допускания!$E$91)/Допускания!$C$92/12)) -> 95 | J32: =IF(Обеми!J4<=12,Допускания!$C$91/Допускания!$C$92/12,IF(Обеми!J4<=24,(Допускания!$C$91+Допускания!$D$91)/Допускания!$C$92/12,(Допускания!$C$91+Допускания!$D$91+Допускания!$E$91)/Допускания!$C$92/12)) -> 95 | ... AL32: =IF(Обеми!AL4<=12,Допускания!$C$91/Допускания!$C$92/12,IF(Обеми!AL4<=24,(Допускания!$C$91+Допускания!$D$91)/Допускания!$C$92/12,(Допускания!$C$91+Допускания!$D$91+Допускания!$E$91)/Допускания!$C$92/12)) -> 273.33333 | AN32: =SUM(C32:N32) -> 1140 | AO32: =SUM(O32:Z32) -> 2160 | AP32: =SUM(AA32:AL32) -> 3280
B33: ПЕЧАЛБА ПРЕДИ ДАНЪЦИ | C33: =C30-C32 -> -3125 | D33: =D30-D32 -> -3125 | E33: =E30-E32 -> -3125 | F33: =F30-F32 -> 4405.3619 | G33: =G30-G32 -> 6515.7685 | H33: =H30-H32 -> 8627.9673 | I33: =I30-I32 -> 9691.4078 | J33: =J30-J32 -> 14957.823 | ... AL33: =AL30-AL32 -> -9040.0107 | AN33: =SUM(C33:N33) -> 46463.102 | AO33: =SUM(O33:Z33) -> 72264.677 | AP33: =SUM(AA33:AL33) -> 134326.26
B34: Корпоративен данък | C34: =IF(C33>0,C33*Допускания!$C$95,0) -> 0 | D34: =IF(D33>0,D33*Допускания!$C$95,0) -> 0 | E34: =IF(E33>0,E33*Допускания!$C$95,0) -> 0 | F34: =IF(F33>0,F33*Допускания!$C$95,0) -> 440.53619 | G34: =IF(G33>0,G33*Допускания!$C$95,0) -> 651.57685 | H34: =IF(H33>0,H33*Допускания!$C$95,0) -> 862.79673 | I34: =IF(I33>0,I33*Допускания!$C$95,0) -> 969.14078 | J34: =IF(J33>0,J33*Допускания!$C$95,0) -> 1495.7823 | ... AL34: =IF(AL33>0,AL33*Допускания!$C$95,0) -> 0 | AN34: =SUM(C34:N34) -> 5869.3998 | AO34: =SUM(O34:Z34) -> 8704.5796 | AP34: =SUM(AA34:AL34) -> 15885.918
B35: ЧИСТА ПЕЧАЛБА | C35: =C33-C34 -> -3125 | D35: =D33-D34 -> -3125 | E35: =E33-E34 -> -3125 | F35: =F33-F34 -> 3964.8257 | G35: =G33-G34 -> 5864.1917 | H35: =H33-H34 -> 7765.1706 | I35: =I33-I34 -> 8722.267 | J35: =J33-J34 -> 13462.041 | ... AL35: =AL33-AL34 -> -9040.0107 | AN35: =SUM(C35:N35) -> 40593.702 | AO35: =SUM(O35:Z35) -> 63560.097 | AP35: =SUM(AA35:AL35) -> 118440.34

Sheet Гаранционен фонд
B1: Гаранционен фонд — математика на риска
B2: Фондът е самозастраховане. Ако салдото стане отрицателно, гаранцията не е обезпечена и моделът се чупи.
B4: Месец № | C4: =Обеми!C4 -> 1 | D4: =Обеми!D4 -> 2 | E4: =Обеми!E4 -> 3 | F4: =Обеми!F4 -> 4 | G4: =Обеми!G4 -> 5 | H4: =Обеми!H4 -> 6 | I4: =Обеми!I4 -> 7 | J4: =Обеми!J4 -> 8 | ... AL4: =Обеми!AL4 -> 36 | AN4: Година 1 | AO4: Година 2 | AP4: Година 3
B5: Изпълнени обекти | C5: =Обеми!C11 -> 0 | D5: =Обеми!D11 -> 0 | E5: =Обеми!E11 -> 0 | F5: =Обеми!F11 -> 2.4761905 | G5: =Обеми!G11 -> 2.9714286 | H5: =Обеми!H11 -> 3.4666667 | I5: =Обеми!I11 -> 3.7142857 | J5: =Обеми!J11 -> 4.952381 | ... AL5: =Обеми!AL11 -> 1.25 | AN5: =SUM(C5:N5) -> 26 | AO5: =SUM(O5:Z5) -> 35 | AP5: =SUM(AA5:AL5) -> 50
B6: Очаквани първи неуспехи | C6: =C5*Допускания!$C$51 -> 0 | D6: =D5*Допускания!$C$51 -> 0 | E6: =E5*Допускания!$C$51 -> 0 | F6: =F5*Допускания!$C$51 -> 0.24761905 | G6: =G5*Допускания!$C$51 -> 0.29714286 | H6: =H5*Допускания!$C$51 -> 0.34666667 | I6: =I5*Допускания!$C$51 -> 0.37142857 | J6: =J5*Допускания!$C$51 -> 0.4952381 | ... AL6: =AL5*Допускания!$C$51 -> 0.125 | AN6: =SUM(C6:N6) -> 2.6 | AO6: =SUM(O6:Z6) -> 3.5 | AP6: =SUM(AA6:AL6) -> 5
B7: Очаквани двойни неуспехи | C7: =C6*Допускания!$C$52 -> 0 | D7: =D6*Допускания!$C$52 -> 0 | E7: =E6*Допускания!$C$52 -> 0 | F7: =F6*Допускания!$C$52 -> 0.086666667 | G7: =G6*Допускания!$C$52 -> 0.104 | H7: =H6*Допускания!$C$52 -> 0.12133333 | I7: =I6*Допускания!$C$52 -> 0.13 | J7: =J6*Допускания!$C$52 -> 0.17333333 | ... AL7: =AL6*Допускания!$C$52 -> 0.04375 | AN7: =SUM(C7:N7) -> 0.91 | AO7: =SUM(O7:Z7) -> 1.225 | AP7: =SUM(AA7:AL7) -> 1.75
B8: Разход за втори опит | C8: =C6*IF(Обеми!C$5=1,Пакети!$C$29,IF(Обеми!C$5=2,Пакети!$D$29,Пакети!$E$29))*Допускания!$C$54 -> 0 | D8: =D6*IF(Обеми!D$5=1,Пакети!$C$29,IF(Обеми!D$5=2,Пакети!$D$29,Пакети!$E$29))*Допускания!$C$54 -> 0 | E8: =E6*IF(Обеми!E$5=1,Пакети!$C$29,IF(Обеми!E$5=2,Пакети!$D$29,Пакети!$E$29))*Допускания!$C$54 -> 0 | F8: =F6*IF(Обеми!F$5=1,Пакети!$C$29,IF(Обеми!F$5=2,Пакети!$D$29,Пакети!$E$29))*Допускания!$C$54 -> 842.20389 | G8: =G6*IF(Обеми!G$5=1,Пакети!$C$29,IF(Обеми!G$5=2,Пакети!$D$29,Пакети!$E$29))*Допускания!$C$54 -> 1010.6447 | H8: =H6*IF(Обеми!H$5=1,Пакети!$C$29,IF(Обеми!H$5=2,Пакети!$D$29,Пакети!$E$29))*Допускания!$C$54 -> 1179.0854 | I8: =I6*IF(Обеми!I$5=1,Пакети!$C$29,IF(Обеми!I$5=2,Пакети!$D$29,Пакети!$E$29))*Допускания!$C$54 -> 1263.3058 | J8: =J6*IF(Обеми!J$5=1,Пакети!$C$29,IF(Обеми!J$5=2,Пакети!$D$29,Пакети!$E$29))*Допускания!$C$54 -> 1684.4078 | ... AL8: =AL6*IF(Обеми!AL$5=1,Пакети!$C$29,IF(Обеми!AL$5=2,Пакети!$D$29,Пакети!$E$29))*Допускания!$C$54 -> 371.889 | AN8: =SUM(C8:N8) -> 8843.1408 | AO8: =SUM(O8:Z8) -> 10980.925 | AP8: =SUM(AA8:AL8) -> 14875.56
B9: Върнати суми при двоен неуспех | C9: =C7*IF(Обеми!C$5=1,Пакети!$C$28,IF(Обеми!C$5=2,Пакети!$D$28,Пакети!$E$28))*Допускания!$C$53 -> 0 | D9: =D7*IF(Обеми!D$5=1,Пакети!$C$28,IF(Обеми!D$5=2,Пакети!$D$28,Пакети!$E$28))*Допускания!$C$53 -> 0 | E9: =E7*IF(Обеми!E$5=1,Пакети!$C$28,IF(Обеми!E$5=2,Пакети!$D$28,Пакети!$E$28))*Допускания!$C$53 -> 0 | F9: =F7*IF(Обеми!F$5=1,Пакети!$C$28,IF(Обеми!F$5=2,Пакети!$D$28,Пакети!$E$28))*Допускания!$C$53 -> 532.04667 | G9: =G7*IF(Обеми!G$5=1,Пакети!$C$28,IF(Обеми!G$5=2,Пакети!$D$28,Пакети!$E$28))*Допускания!$C$53 -> 638.456 | H9: =H7*IF(Обеми!H$5=1,Пакети!$C$28,IF(Обеми!H$5=2,Пакети!$D$28,Пакети!$E$28))*Допускания!$C$53 -> 744.86533 | I9: =I7*IF(Обеми!I$5=1,Пакети!$C$28,IF(Обеми!I$5=2,Пакети!$D$28,Пакети!$E$28))*Допускания!$C$53 -> 798.07 | J9: =J7*IF(Обеми!J$5=1,Пакети!$C$28,IF(Обеми!J$5=2,Пакети!$D$28,Пакети!$E$28))*Допускания!$C$53 -> 1064.0933 | ... AL9: =AL7*IF(Обеми!AL$5=1,Пакети!$C$28,IF(Обеми!AL$5=2,Пакети!$D$28,Пакети!$E$28))*Допускания!$C$53 -> 324.98331 | AN9: =SUM(C9:N9) -> 5586.49 | AO9: =SUM(O9:Z9) -> 8272.3025 | AP9: =SUM(AA9:AL9) -> 12999.333
B10: ОБЩ ОЧАКВАН РАЗХОД ПО РИСКА | C10: =C8+C9 -> 0 | D10: =D8+D9 -> 0 | E10: =E8+E9 -> 0 | F10: =F8+F9 -> 1374.2506 | G10: =G8+G9 -> 1649.1007 | H10: =H8+H9 -> 1923.9508 | I10: =I8+I9 -> 2061.3758 | J10: =J8+J9 -> 2748.5011 | ... AL10: =AL8+AL9 -> 696.87231 | AN10: =SUM(C10:N10) -> 14429.631 | AO10: =SUM(O10:Z10) -> 19253.228 | AP10: =SUM(AA10:AL10) -> 27874.892
B11: Отчисления във фонда | C11: =ОПР!C18 -> 0 | D11: =ОПР!D18 -> 0 | E11: =ОПР!E18 -> 0 | F11: =ОПР!F18 -> 1737.2952 | G11: =ОПР!G18 -> 2084.7543 | H11: =ОПР!H18 -> 2432.2133 | I11: =ОПР!I18 -> 2605.9429 | J11: =ОПР!J18 -> 3474.5905 | ... AL11: =ОПР!AL18 -> 1061.17 | AN11: =SUM(C11:N11) -> 18241.6 | AO11: =SUM(O11:Z11) -> 27011.6 | AP11: =SUM(AA11:AL11) -> 42446.8
B13: Салдо на фонда — начало | C13: =Допускания!$C$94 -> 10000 | D13: =C14 -> 10000 | E13: =D14 -> 10000 | F13: =E14 -> 10000 | G13: =F14 -> 10363.045 | H13: =G14 -> 10798.698 | I13: =H14 -> 11306.961 | J13: =I14 -> 11851.528 | K13: =J14 -> 12577.617 | ... AL13: =AK14 -> 35777.951
B14: Салдо на фонда — край | C14: =C13+C11-C10 -> 10000 | D14: =D13+D11-D10 -> 10000 | E14: =E13+E11-E10 -> 10000 | F14: =F13+F11-F10 -> 10363.045 | G14: =G13+G11-G10 -> 10798.698 | H14: =H13+H11-H10 -> 11306.961 | I14: =I13+I11-I10 -> 11851.528 | J14: =J13+J11-J10 -> 12577.617 | ... AL14: =AL13+AL11-AL10 -> 36142.249
B15: Контрола: фондът покрит ли е? | C15: =IF(C14>=0,"ОК","НЕДОСТИГ") -> ОК | D15: =IF(D14>=0,"ОК","НЕДОСТИГ") -> ОК | E15: =IF(E14>=0,"ОК","НЕДОСТИГ") -> ОК | F15: =IF(F14>=0,"ОК","НЕДОСТИГ") -> ОК | G15: =IF(G14>=0,"ОК","НЕДОСТИГ") -> ОК | H15: =IF(H14>=0,"ОК","НЕДОСТИГ") -> ОК | I15: =IF(I14>=0,"ОК","НЕДОСТИГ") -> ОК | J15: =IF(J14>=0,"ОК","НЕДОСТИГ") -> ОК | ... AL15: =IF(AL14>=0,"ОК","НЕДОСТИГ") -> ОК
B17: ОБОБЩЕНИЕ ЗА ТРИТЕ ГОДИНИ
B18: Общо отчисления | C18: =SUM(C11:AL11) -> 87700
B19: Общ очакван разход по риска | C19: =SUM(C10:AL10) -> 61557.751
B20: Покритие (отчисления / разход) | C20: =IF(C19=0,0,C18/C19) -> 1.4246784
B21: Минимално салдо на фонда през 36 месеца | C21: =MIN(C14:AL14) -> 10000
B22: Колко двойни неуспеха издържа фондът в най-слабия си момент | C22: =IF(Пакети!$C$28=0,0,C21/(Пакети!$D$28*Допускания!$C$53)) -> 1.4808453
B23: Под 3 е опасно: при малък обем в началото няколко последователни неуспеха изчерпват фонда, преди отчисленията да са го напълнили.

Sheet Паричен поток
B1: Паричен поток, месечно
B2: Минималното салдо определя колко капитал реално е нужен. Гаранционният фонд се държи отделно от оперативната каса.
B4: Месец № | C4: =Обеми!C4 -> 1 | D4: =Обеми!D4 -> 2 | E4: =Обеми!E4 -> 3 | F4: =Обеми!F4 -> 4 | G4: =Обеми!G4 -> 5 | H4: =Обеми!H4 -> 6 | I4: =Обеми!I4 -> 7 | J4: =Обеми!J4 -> 8 | ... AL4: =Обеми!AL4 -> 36 | AN4: Година 1 | AO4: Година 2 | AP4: Година 3
B5: Инкасирани приходи | C5: =ОПР!C10*Допускания!$C$98 -> 0 | D5: =ОПР!D10*Допускания!$C$98+ОПР!C10*(1-Допускания!$C$98) -> 0 | E5: =ОПР!E10*Допускания!$C$98+ОПР!D10*(1-Допускания!$C$98) -> 0 | F5: =ОПР!F10*Допускания!$C$98+ОПР!E10*(1-Допускания!$C$98) -> 24220.337 | G5: =ОПР!G10*Допускания!$C$98+ОПР!F10*(1-Допускания!$C$98) -> 31767.933 | H5: =ОПР!H10*Допускания!$C$98+ОПР!G10*(1-Допускания!$C$98) -> 37166.363 | I5: =ОПР!I10*Допускания!$C$98+ОПР!H10*(1-Допускания!$C$98) -> 40145.381 | J5: =ОПР!J10*Допускания!$C$98+ОПР!I10*(1-Допускания!$C$98) -> 52544.783 | K5: =ОПР!K10*Допускания!$C$98+ОПР!J10*(1-Допускания!$C$98) -> 36962.406 | ... AL5: =ОПР!AL10*Допускания!$C$98+ОПР!AK10*(1-Допускания!$C$98) -> 19175.308 | AN5: =SUM(C5:N5) -> 282385.96 | AO5: =SUM(O5:Z5) -> 420723.06 | AP5: =SUM(AA5:AL5) -> 661831.66
B6: Платени преки разходи (без отчисленията) | C6: =-(ОПР!C19-ОПР!C18)*Допускания!$C$100 -> 0 | D6: =-(ОПР!D19-ОПР!D18)*Допускания!$C$100 -> 0 | E6: =-(ОПР!E19-ОПР!E18)*Допускания!$C$100 -> 0 | F6: =-(ОПР!F19-ОПР!F18)*Допускания!$C$100 -> -14668.829 | G6: =-(ОПР!G19-ОПР!G18)*Допускания!$C$100 -> -17607.016 | H6: =-(ОПР!H19-ОПР!H18)*Допускания!$C$100 -> -20546.052 | I6: =-(ОПР!I19-ОПР!I18)*Допускания!$C$100 -> -22019.047 | J6: =-(ОПР!J19-ОПР!J18)*Допускания!$C$100 -> -29359.967 | ... AL6: =-(ОПР!AL19-ОПР!AL18)*Допускания!$C$100 -> -6841.4686 | AN6: =SUM(C6:N6) -> -154227.24 | AO6: =SUM(O6:Z6) -> -195342.9 | AP6: =SUM(AA6:AL6) -> -268212.01
B7: Платени оперативни разходи | C7: =-ОПР!C28 -> -3030 | D7: =-ОПР!D28 -> -3030 | E7: =-ОПР!E28 -> -3030 | F7: =-ОПР!F28 -> -6005 | G7: =-ОПР!G28 -> -6005 | H7: =-ОПР!H28 -> -6005 | I7: =-ОПР!I28 -> -6005 | J7: =-ОПР!J28 -> -6005 | ... AL7: =-ОПР!AL28 -> -17849 | AN7: =SUM(C7:N7) -> -63135 | AO7: =SUM(O7:Z7) -> -124200 | AP7: =SUM(AA7:AL7) -> -214188
B8: Прехвърляне в гаранционния фонд | C8: =-ОПР!C18 -> 0 | D8: =-ОПР!D18 -> 0 | E8: =-ОПР!E18 -> 0 | F8: =-ОПР!F18 -> -1737.2952 | G8: =-ОПР!G18 -> -2084.7543 | H8: =-ОПР!H18 -> -2432.2133 | I8: =-ОПР!I18 -> -2605.9429 | J8: =-ОПР!J18 -> -3474.5905 | ... AL8: =-ОПР!AL18 -> -1061.17 | AN8: =SUM(C8:N8) -> -18241.6 | AO8: =SUM(O8:Z8) -> -27011.6 | AP8: =SUM(AA8:AL8) -> -42446.8
B9: Платен данък | C9: =-IF(MOD(Обеми!C4,12)=0,SUM(OFFSET(ОПР!C34,0,-11,1,12)),0) -> 0 | D9: =-IF(MOD(Обеми!D4,12)=0,SUM(OFFSET(ОПР!D34,0,-11,1,12)),0) -> 0 | E9: =-IF(MOD(Обеми!E4,12)=0,SUM(OFFSET(ОПР!E34,0,-11,1,12)),0) -> 0 | F9: =-IF(MOD(Обеми!F4,12)=0,SUM(OFFSET(ОПР!F34,0,-11,1,12)),0) -> 0 | G9: =-IF(MOD(Обеми!G4,12)=0,SUM(OFFSET(ОПР!G34,0,-11,1,12)),0) -> 0 | H9: =-IF(MOD(Обеми!H4,12)=0,SUM(OFFSET(ОПР!H34,0,-11,1,12)),0) -> 0 | I9: =-IF(MOD(Обеми!I4,12)=0,SUM(OFFSET(ОПР!I34,0,-11,1,12)),0) -> 0 | J9: =-IF(MOD(Обеми!J4,12)=0,SUM(OFFSET(ОПР!J34,0,-11,1,12)),0) -> 0 | ... AL9: =-IF(MOD(Обеми!AL4,12)=0,SUM(OFFSET(ОПР!AL34,0,-11,1,12)),0) -> -15885.918 | AN9: =SUM(C9:N9) -> -5869.3998 | AO9: =SUM(O9:Z9) -> -8704.5796 | AP9: =SUM(AA9:AL9) -> -15885.918
B10: Инвестиции | C10: =-IF(Обеми!C4<=3,IF(Обеми!C4=1,Допускания!$C$91*0.6,IF(Обеми!C4=2,Допускания!$C$91*0.4,0)),IF(Обеми!C4=13,Допускания!$D$91,IF(Обеми!C4=25,Допускания!$E$91,0))) -> -3420 | D10: =-IF(Обеми!D4<=3,IF(Обеми!D4=1,Допускания!$C$91*0.6,IF(Обеми!D4=2,Допускания!$C$91*0.4,0)),IF(Обеми!D4=13,Допускания!$D$91,IF(Обеми!D4=25,Допускания!$E$91,0))) -> -2280 | E10: =-IF(Обеми!E4<=3,IF(Обеми!E4=1,Допускания!$C$91*0.6,IF(Обеми!E4=2,Допускания!$C$91*0.4,0)),IF(Обеми!E4=13,Допускания!$D$91,IF(Обеми!E4=25,Допускания!$E$91,0))) -> 0 | F10: =-IF(Обеми!F4<=3,IF(Обеми!F4=1,Допускания!$C$91*0.6,IF(Обеми!F4=2,Допускания!$C$91*0.4,0)),IF(Обеми!F4=13,Допускания!$D$91,IF(Обеми!F4=25,Допускания!$E$91,0))) -> 0 | G10: =-IF(Обеми!G4<=3,IF(Обеми!G4=1,Допускания!$C$91*0.6,IF(Обеми!G4=2,Допускания!$C$91*0.4,0)),IF(Обеми!G4=13,Допускания!$D$91,IF(Обеми!G4=25,Допускания!$E$91,0))) -> 0 | H10: =-IF(Обеми!H4<=3,IF(Обеми!H4=1,Допускания!$C$91*0.6,IF(Обеми!H4=2,Допускания!$C$91*0.4,0)),IF(Обеми!H4=13,Допускания!$D$91,IF(Обеми!H4=25,Допускания!$E$91,0))) -> 0 | I10: =-IF(Обеми!I4<=3,IF(Обеми!I4=1,Допускания!$C$91*0.6,IF(Обеми!I4=2,Допускания!$C$91*0.4,0)),IF(Обеми!I4=13,Допускания!$D$91,IF(Обеми!I4=25,Допускания!$E$91,0))) -> 0 | J10: =-IF(Обеми!J4<=3,IF(Обеми!J4=1,Допускания!$C$91*0.6,IF(Обеми!J4=2,Допускания!$C$91*0.4,0)),IF(Обеми!J4=13,Допускания!$D$91,IF(Обеми!J4=25,Допускания!$E$91,0))) -> 0 | ... AL10: =-IF(Обеми!AL4<=3,IF(Обеми!AL4=1,Допускания!$C$91*0.6,IF(Обеми!AL4=2,Допускания!$C$91*0.4,0)),IF(Обеми!AL4=13,Допускания!$D$91,IF(Обеми!AL4=25,Допускания!$E$91,0))) -> 0 | AN10: =SUM(C10:N10) -> -5700 | AO10: =SUM(O10:Z10) -> -5100 | AP10: =SUM(AA10:AL10) -> -5600
B11: Внесен собствен капитал | C11: =Допускания!$C$93-Допускания!$C$94 -> 40000 | D11: =0 -> 0 | E11: =0 -> 0 | F11: =0 -> 0 | G11: =0 -> 0 | H11: =0 -> 0 | I11: =0 -> 0 | J11: =0 -> 0 | K11: =0 -> 0 | ... AL11: =0 -> 0 | AN11: =SUM(C11:N11) -> 40000 | AO11: =SUM(O11:Z11) -> 0 | AP11: =SUM(AA11:AL11) -> 0
B12: НЕТЕН ПАРИЧЕН ПОТОК | C12: =SUM(C5:C11) -> 33550 | D12: =SUM(D5:D11) -> -5310 | E12: =SUM(E5:E11) -> -3030 | F12: =SUM(F5:F11) -> 1809.2133 | G12: =SUM(G5:G11) -> 6071.1632 | H12: =SUM(H5:H11) -> 8183.0979 | I12: =SUM(I5:I11) -> 9515.3913 | J12: =SUM(J5:J11) -> 13705.225 | ... AL12: =SUM(AL5:AL11) -> -22462.249 | AN12: =SUM(C12:N12) -> 75212.727 | AO12: =SUM(O12:Z12) -> 60363.988 | AP12: =SUM(AA12:AL12) -> 115498.93
B14: Каса — начало | C14: =0 -> 0 | D14: =C15 -> 33550 | E14: =D15 -> 28240 | F14: =E15 -> 25210 | G14: =F15 -> 27019.213 | H14: =G15 -> 33090.377 | I14: =H15 -> 41273.475 | J14: =I15 -> 50788.866 | K14: =J15 -> 64494.091 | ... AL14: =AK15 -> 273537.89
B15: КАСА — КРАЙ | C15: =C14+C12 -> 33550 | D15: =D14+D12 -> 28240 | E15: =E14+E12 -> 25210 | F15: =F14+F12 -> 27019.213 | G15: =G14+G12 -> 33090.377 | H15: =H14+H12 -> 41273.475 | I15: =I14+I12 -> 50788.866 | J15: =J14+J12 -> 64494.091 | ... AL15: =AL14+AL12 -> 251075.64
B16: Гаранционен фонд (отделна сметка) | C16: ='Гаранционен фонд'!C14 -> 10000 | D16: ='Гаранционен фонд'!D14 -> 10000 | E16: ='Гаранционен фонд'!E14 -> 10000 | F16: ='Гаранционен фонд'!F14 -> 10363.045 | G16: ='Гаранционен фонд'!G14 -> 10798.698 | H16: ='Гаранционен фонд'!H14 -> 11306.961 | I16: ='Гаранционен фонд'!I14 -> 11851.528 | J16: ='Гаранционен фонд'!J14 -> 12577.617 | ... AL16: ='Гаранционен фонд'!AL14 -> 36142.249
B17: ОБЩО ЛИКВИДНОСТ | C17: =C15+C16 -> 43550 | D17: =D15+D16 -> 38240 | E17: =E15+E16 -> 35210 | F17: =F15+F16 -> 37382.258 | G17: =G15+G16 -> 43889.075 | H17: =H15+H16 -> 52580.435 | I17: =I15+I16 -> 62640.394 | J17: =J15+J16 -> 77071.708 | ... AL17: =AL15+AL16 -> 287217.89
B19: КОНТРОЛНИ ПОКАЗАТЕЛИ
B20: Минимална оперативна каса за 36 месеца | C20: =MIN(C15:AL15) -> 25210
B21: Месец на минимума | C21: =MATCH(MIN(C15:AL15),C15:AL15,0) -> 3
B22: Достатъчен ли е капиталът? | C22: =IF(C20>=0,"ДА","НЕ — увеличи капитала") -> ДА
B23: Препоръчителен собствен капитал (с 20% буфер) | C23: =ROUND(MAX(Допускания!$C$93,Допускания!$C$93-MIN(C15:AL15)*1.2)/1000,0)*1000 -> 50000
B24: Първи месец с положителна EBITDA | C24: =IFERROR(MATCH(TRUE(),INDEX(ОПР!C30:AL30>0,0),0),0) -> 4
B25: Кумулативна EBITDA за 36 месеца | C25: =SUM(ОПР!C30:AL30) -> 259634.04

Sheet Годишно резюме
B1: Три години на един екран
B2: Всички числа идват от останалите листове.
B4: Показател | C4: Година 1 | D4: Година 2 | E4: Година 3 | F4: Общо | G4: Бележка
B5: Изпълнени обекти | C5: =Обеми!AN11 -> 26 | D5: =Обеми!AO11 -> 35 | E5: =Обеми!AP11 -> 50 | F5: =SUM(C5:E5) -> 111
B6: Линейни метри сондиране | C6: =Обеми!AN12 -> 1470.3 | D6: =Обеми!AO12 -> 1979.25 | E6: =Обеми!AP12 -> 2827.5 | F6: =SUM(C6:E6) -> 6277.05 | G6: Това е числото, което носиш на бригадата при преговори.
B8: ПРИХОДИ
B9: Приход от пакети | C9: =ОПР!AN6 -> 228020 | D9: =ОПР!AO6 -> 337645 | E9: =ОПР!AP6 -> 530585 | F9: =SUM(C9:E9) -> 1096250
B10: Приход от допълнителни продажби | C10: =ОПР!AN7 -> 54405 | D10: =ОПР!AO7 -> 80561.25 | E10: =ОПР!AP7 -> 126596.25 | F10: =SUM(C10:E10) -> 261562.5
B11: Приход от абонаменти | C11: =ОПР!AN9 -> 767.97628 | D11: =ОПР!AO9 -> 2723.4071 | E11: =ОПР!AP9 -> 5177.6847 | F11: =SUM(C11:E11) -> 8669.0681 | G11: Единственият повтарящ се приход в модела.
B12: ОБЩО ПРИХОДИ | C12: =ОПР!AN10 -> 283206.94 | D12: =ОПР!AO10 -> 420979.17 | E12: =ОПР!AP10 -> 662453.07 | F12: =SUM(C12:E12) -> 1366639.2
B14: РЕНТАБИЛНОСТ
B15: Брутна печалба | C15: =ОПР!AN21 -> 110738.1 | D15: =ОПР!AO21 -> 198624.68 | E15: =ОПР!AP21 -> 351794.26 | F15: =SUM(C15:E15) -> 661157.04
B16: Брутен марж | C16: =IF(C12=0,0,C15/C12) -> 0.39101479 | D16: =IF(D12=0,0,D15/D12) -> 0.47181592 | E16: =IF(E12=0,0,E15/E12) -> 0.53104782
B17: Оперативни разходи | C17: =ОПР!AN28 -> 63135 | D17: =ОПР!AO28 -> 124200 | E17: =ОПР!AP28 -> 214188 | F17: =SUM(C17:E17) -> 401523
B18: EBITDA | C18: =ОПР!AN30 -> 47603.102 | D18: =ОПР!AO30 -> 74424.677 | E18: =ОПР!AP30 -> 137606.26 | F18: =SUM(C18:E18) -> 259634.04
B19: EBITDA марж | C19: =IF(C12=0,0,C18/C12) -> 0.16808593 | D19: =IF(D12=0,0,D18/D12) -> 0.17678945 | E19: =IF(E12=0,0,E18/E12) -> 0.20772227
B20: Амортизация | C20: =ОПР!AN32 -> 1140 | D20: =ОПР!AO32 -> 2160 | E20: =ОПР!AP32 -> 3280 | F20: =SUM(C20:E20) -> 6580
B21: Печалба преди данъци | C21: =ОПР!AN33 -> 46463.102 | D21: =ОПР!AO33 -> 72264.677 | E21: =ОПР!AP33 -> 134326.26 | F21: =SUM(C21:E21) -> 253054.04
B22: Данък | C22: =ОПР!AN34 -> 5869.3998 | D22: =ОПР!AO34 -> 8704.5796 | E22: =ОПР!AP34 -> 15885.918 | F22: =SUM(C22:E22) -> 30459.898
B23: ЧИСТА ПЕЧАЛБА | C23: =ОПР!AN35 -> 40593.702 | D23: =ОПР!AO35 -> 63560.097 | E23: =ОПР!AP35 -> 118440.34 | F23: =SUM(C23:E23) -> 222594.14
B25: ПОКАЗАТЕЛИ НА ЕДИНИЦА
B26: Приход на обект | C26: =IF(Обеми!AN11=0,0,C12/Обеми!AN11) -> 10892.575 | D26: =IF(Обеми!AO11=0,0,D12/Обеми!AO11) -> 12027.976 | E26: =IF(Обеми!AP11=0,0,E12/Обеми!AP11) -> 13249.061
B27: Брутна печалба на обект | C27: =IF(Обеми!AN11=0,0,C15/Обеми!AN11) -> 4259.1578 | D27: =IF(Обеми!AO11=0,0,D15/Обеми!AO11) -> 5674.9908 | E27: =IF(Обеми!AP11=0,0,E15/Обеми!AP11) -> 7035.8852
B28: Оперативни разходи на обект | C28: =IF(Обеми!AN11=0,0,ОПР!AN28/Обеми!AN11) -> 2428.2692 | D28: =IF(Обеми!AO11=0,0,ОПР!AO28/Обеми!AO11) -> 3548.5714 | E28: =IF(Обеми!AP11=0,0,ОПР!AP28/Обеми!AP11) -> 4283.76
B29: Праг на рентабилност (обекти на година) | C29: =IF(Обеми!AN11=0,0,ОПР!AN28/(C15/Обеми!AN11)) -> 14.823353 | D29: =IF(Обеми!AO11=0,0,ОПР!AO28/(D15/Обеми!AO11)) -> 21.885498 | E29: =IF(Обеми!AP11=0,0,ОПР!AP28/(E15/Обеми!AP11)) -> 30.442225 | G29: Колко обекта трябват само за да се покрият оперативните разходи.
B31: ПАРИ
B32: Нетен паричен поток | C32: ='Паричен поток'!AN12 -> 75212.727 | D32: ='Паричен поток'!AO12 -> 60363.988 | E32: ='Паричен поток'!AP12 -> 115498.93 | F32: =SUM(C32:E32) -> 251075.64
B33: Каса в края на годината | C33: ='Паричен поток'!N15 -> 75212.727 | D33: ='Паричен поток'!Z15 -> 135576.71 | E33: ='Паричен поток'!AL15 -> 251075.64
B34: Обща ликвидност в края на годината | C34: ='Паричен поток'!N17 -> 89024.696 | D34: ='Паричен поток'!Z17 -> 157147.06 | E34: ='Паричен поток'!AL17 -> 287217.89

Sheet Сценарии
B1: Сценарии и чувствителност
B2: Смени сценария от Допускания!C6. Таблицата за чувствителност по-долу е самостоятелен опростен разчет.
B4: Лост | D4: 1 — Консервативен | E4: 2 — Базов | F4: 3 — Агресивен | G4: Коментар
B5: Множител на обема | D5: 0.65 | E5: 1 | F5: 1.35 | G5: Колко обекта успяваш да продадеш спрямо плана.
B6: Множител на цените | D6: 0.94 | E6: 1 | F6: 1.05 | G6: Ценови натиск от сивия сектор срещу успешно позициониране на гаранцията.
B7: Множител на цената на подизпълнителя | D7: 1.1 | E7: 1 | F7: 0.93 | G7: Не успяваш да договориш отстъпка срещу рамков договор с реален обем.
B9: Активен сценарий сега | C9: =Допускания!$C$5 -> 2 | D9: =INDEX({"Консервативен";"Базов";"Агресивен"},Допускания!$C$5) -> Базов
B11: РЕЗУЛТАТ ПРИ АКТИВНИЯ СЦЕНАРИЙ
B12: Показател | C12: Година 1 | D12: Година 2 | E12: Година 3
B13: Приходи | C13: =ОПР!AN10 -> 283206.94 | D13: =ОПР!AO10 -> 420979.17 | E13: =ОПР!AP10 -> 662453.07
B14: EBITDA | C14: =ОПР!AN30 -> 47603.102 | D14: =ОПР!AO30 -> 74424.677 | E14: =ОПР!AP30 -> 137606.26
B15: Чиста печалба | C15: =ОПР!AN35 -> 40593.702 | D15: =ОПР!AO35 -> 63560.097 | E15: =ОПР!AP35 -> 118440.34
